Workbook

Sheet README
A1: Café Sales Analysis
A2: Excel data-analysis project: cleaning, summarising and reporting on 160 café orders across 5 Indian cities (March 2026).
A4: 1. PROJECT OVERVIEW
A5: Business questions | B5: Which city earns the most? How much money is lost to cancelled and refunded orders? Which payment method do customers prefer?
A6: Dataset | B6: 160 unique orders (170 raw rows, 10 duplicates removed), 1–30 Mar 2026. Cities: Bengaluru, Chennai, Delhi, Mumbai, Pune. Amounts in rupees (₹).
A7: Tools / skills | B7: Microsoft Excel: TRIM/PROPER cleaning, IF logic, SUMIFS, COUNTIFS, RANK, INDEX/MATCH, dynamic text, conditional formatting, charts.
A9: 2. WORKBOOK GUIDE
A10: Summary | B10: Key numbers, plain-English findings, recommendation, 4 charts and the tables behind them.
A11: Orders Data | B11: 160 cleaned orders. Blue headers = recorded data, green = formula columns, grey (P:R) = original messy entries, red rows = invalid orders.
A12: City x Status | B12: Formula-based pivot: sales by city and order status (reconciles to the Summary total).
A14: 3. WORKFLOW FOLLOWED
A15: 1. Understand | B15: One row = one order. Order Status shows whether money was actually kept.
A16: 2. Clean | B16: Removed 10 duplicate Order IDs; fixed spacing/capitalisation in City, Customer, Status with TRIM(PROPER()); flagged 21 orders with missing/invalid Quantity or Price.
A17: 3. Transform | B17: Added Sales Value (Qty × Price), Order Size, Counted as a Sale?, Data Issue columns.
A18: 4. Summarise | B18: SUMIFS/COUNTIFS tables by city, status, category and payment method, with check cells that must reconcile.
A19: 5. Visualise | B19: Bar and pie charts on the Summary sheet.
A20: 6. Report | B20: Findings and a recommendation for the manager.
A22: 4. DATA DICTIONARY (Orders Data)
A23: Order ID | B23: Unique order number (ORD2001–ORD2160).
A24: Date | B24: Order date.
A25: Customer | B25: Cleaned customer name (formula).
A26: Product / Category | B26: Item sold; Beverage, Bakery or Food.
A27: Quantity / Price (₹) | B27: Units ordered and unit price.
A28: Payment Method | B28: Card, Cash or UPI.
A29: City / Order Status | B29: Cleaned by formula from the raw entries in columns Q and R.
A30: Sales Value (₹) | B30: Quantity × Price; 0 when the row has a data issue.
A31: Order Size | B31: Bulk (3+ items) or Regular.
A32: Counted as a Sale? | B32: Yes only when status is Completed.
A33: Data Issue | B33: Quantity missing / Quantity invalid / Price missing; blank when clean.
A34: P:R | B34: Original uncleaned Customer, City and Status, kept for audit.
A36: 5. KEY FINDINGS
A37: Total sales / kept | B37: ₹46,500 total; ₹32,990 kept from Completed orders; ₹13,510 (29%) lost to cancelled and refunded orders.
A38: Completion rate | B38: 70.6% of orders completed (20 cancelled, 27 refunded). Average completed order ≈ ₹330.
A39: Best city | B39: Pune keeps the most sales (₹8,450) and loses the smallest share (15%). Mumbai leads on total sales (₹10,980) but ranks #2 after losses.
A40: Weak spot | B40: Chennai loses 58% of its sales to cancelled/refunded orders vs 29% overall.
A41: Payments / Category | B41: UPI has the highest sales (₹16,210), but usage across Card, Cash and UPI is fairly even. Beverages bring 67% of kept sales.
A42: Recommendation | B42: Investigate why Chennai orders fail (payment, delivery, stock) and confirm orders at checkout; replicate Pune’s practices in other cities.
A44: 6. NOTES
A45: Live formulas | B45: All results are formulas on Orders Data; edit the data and everything updates. Findings text above is a snapshot of the current data.
A46: Assumptions | B46: Revenue = Quantity × Price on valid rows only; invalid rows count as ₹0 but remain in the data.

Sheet Summary
A1: Café Sales Analysis
A2: ="Orders placed "&TEXT(MIN('Orders Data'!$B$2:$B$161),"d mmm yyyy")&" to "&TEXT(MAX('Orders Data'!$B$2:$B$161),"d mmm yyyy")&" | "&COUNTA('Orders Data'!$A$2:$A$161)&" orders | 5 cities | all amounts in rupees (₹)" -> Orders placed 1 Mar 2026 to 30 Mar 2026 | 160 orders | 5 cities | all amounts in rupees (₹)
A3: This report answers three questions: Which city earns the most? How much money is lost to cancelled and refunded orders? Which payment method do customers prefer?
A4: KEY NUMBERS
A5: Total orders | C5: Total sales | E5: Sales kept | G5: Completion rate | I5: Sales lost | K5: Avg. completed order
A6: =COUNTA('Orders Data'!$A$2:$A$161) -> 160 | C6: =SUM('Orders Data'!$K$2:$K$161) -> 46500 | E6: =SUMIFS('Orders Data'!$K$2:$K$161,'Orders Data'!$J$2:$J$161,"Completed") -> 32990 | G6: =COUNTIFS('Orders Data'!$J$2:$J$161,"Completed")/A6 -> 0.70625 | I6: =C6-E6 -> 13510 | K6: =E6/COUNTIFS('Orders Data'!$J$2:$J$161,"Completed",'Orders Data'!$N$2:$N$161,"") -> 329.9
A7: unique orders after cleaning | C7: if every order is counted | E7: from Completed orders only | G7: of orders were completed | I7: to cancelled and refunded orders | K7: typical value of one sale
A9: WHAT THE DATA TELLS US (in plain English)
A10: ="1. "&INDEX($A$64:$A$68,MATCH(MAX($C$64:$C$68),$C$64:$C$68,0))&" is the best-performing city: it kept the most sales from completed orders (₹"&TEXT(MAX($C$64:$C$68),"#,##0")&")." -> 1. Pune is the best-performing city: it kept the most sales from completed orders (₹8,450).
A11: ="2. "&INDEX($A$64:$A$68,MATCH(MAX($B$64:$B$68),$B$64:$B$68,0))&" has the highest total sales if every order is counted (₹"&TEXT(MAX($B$64:$B$68),"#,##0")&"), but it ranks #"&INDEX($F$64:$F$68,MATCH(MAX($B$64:$B$68),$B$64:$B$68,0))&" once cancelled and refunded orders are removed." -> 2. Mumbai has the highest total sales if every order is counted (₹10,980), but it ranks #2 once cancelled and refunded orders are removed.
A12: ="3. "&INDEX($A$64:$A$68,MATCH(MAX($E$64:$E$68),$E$64:$E$68,0))&" is the weak spot: "&TEXT(MAX($E$64:$E$68),"0%")&" of its sales (₹"&TEXT(INDEX($D$64:$D$68,MATCH(MAX($E$64:$E$68),$E$64:$E$68,0)),"#,##0")&") come from cancelled or refunded orders, compared with "&TEXT($E$69,"0%")&" for the whole business." -> 3. Chennai is the weak spot: 58% of its sales (₹3,620) come from cancelled or refunded orders, compared with 29% for the whole business.
A13: ="4. Overall, "&TEXT($G$6,"0%")&" of orders were completed; "&$I$65&" were cancelled and "&$I$66&" were refunded." -> 4. Overall, 71% of orders were completed; 20 were cancelled and 27 were refunded.
A14: ="5. "&INDEX($H$73:$H$75,MATCH(MAX($I$73:$I$75),$I$73:$I$75,0))&" is the most-used payment method ("&TEXT(MAX($I$73:$I$75)/$I$76,"0%")&" of valid orders), but Card, Cash and UPI are used fairly evenly." -> 5. UPI is the most-used payment method (36% of valid orders), but Card, Cash and UPI are used fairly evenly.
A15: ="6. "&INDEX($A$73:$A$75,MATCH(MAX($C$73:$C$75),$C$73:$C$75,0))&" products bring in the most kept sales (₹"&TEXT(MAX($C$73:$C$75),"#,##0")&", "&TEXT(MAX($C$73:$C$75)/$C$76,"0%")&" of the total)." -> 6. Beverage products bring in the most kept sales (₹22,020, 67% of the total).
A17: OUR RECOMMENDATION
A18: Focus on Chennai first. More than half of its sales (58%) are lost to cancelled or refunded orders, far above the 29% average, so fixing this is the biggest opportunity. Find out why Chennai orders fail (payment problems, delivery delays or stock issues) and confirm orders at checkout. Then copy what works in Pune, which keeps the largest share of its sales, in the other cities. (Based on the figures in this workbook; update the wording if the data changes.)
A23: CHARTS
A60: THE NUMBERS BEHIND THE CHARTS
A62: Sales by city | H62: Orders by status
A63: City | B63: Total sales (all orders) | C63: Sales kept (Completed only) | D63: Sales lost (Cancelled + Refunded) | E63: % of sales lost | F63: Rank (1 = best kept sales) | H63: Order status | I63: Orders | J63: % of orders | K63: Sales value
A64: Bengaluru | B64: =SUMIFS('Orders Data'!$K$2:$K$161,'Orders Data'!$I$2:$I$161,A64) -> 10100 | C64: =SUMIFS('Orders Data'!$K$2:$K$161,'Orders Data'!$I$2:$I$161,A64,'Orders Data'!$J$2:$J$161,"Completed") -> 7280 | D64: =B64-C64 -> 2820 | E64: =IF(B64=0,0,D64/B64) -> 0.27920792 | F64: =RANK(C64,$C$64:$C$68) -> 3 | H64: Completed | I64: =COUNTIFS('Orders Data'!$J$2:$J$161,H64) -> 113 | J64: =I64/$A$6 -> 0.70625 | K64: =SUMIFS('Orders Data'!$K$2:$K$161,'Orders Data'!$J$2:$J$161,H64) -> 32990
A65: Chennai | B65: =SUMIFS('Orders Data'!$K$2:$K$161,'Orders Data'!$I$2:$I$161,A65) -> 6220 | C65: =SUMIFS('Orders Data'!$K$2:$K$161,'Orders Data'!$I$2:$I$161,A65,'Orders Data'!$J$2:$J$161,"Completed") -> 2600 | D65: =B65-C65 -> 3620 | E65: =IF(B65=0,0,D65/B65) -> 0.58199357 | F65: =RANK(C65,$C$64:$C$68) -> 5 | H65: Cancelled | I65: =COUNTIFS('Orders Data'!$J$2:$J$161,H65) -> 20 | J65: =I65/$A$6 -> 0.125 | K65: =SUMIFS('Orders Data'!$K$2:$K$161,'Orders Data'!$J$2:$J$161,H65) -> 6410
A66: Delhi | B66: =SUMIFS('Orders Data'!$K$2:$K$161,'Orders Data'!$I$2:$I$161,A66) -> 9290 | C66: =SUMIFS('Orders Data'!$K$2:$K$161,'Orders Data'!$I$2:$I$161,A66,'Orders Data'!$J$2:$J$161,"Completed") -> 6830 | D66: =B66-C66 -> 2460 | E66: =IF(B66=0,0,D66/B66) -> 0.26480086 | F66: =RANK(C66,$C$64:$C$68) -> 4 | H66: Refunded | I66: =COUNTIFS('Orders Data'!$J$2:$J$161,H66) -> 27 | J66: =I66/$A$6 -> 0.16875 | K66: =SUMIFS('Orders Data'!$K$2:$K$161,'Orders Data'!$J$2:$J$161,H66) -> 7100
A67: Mumbai | B67: =SUMIFS('Orders Data'!$K$2:$K$161,'Orders Data'!$I$2:$I$161,A67) -> 10980 | C67: =SUMIFS('Orders Data'!$K$2:$K$161,'Orders Data'!$I$2:$I$161,A67,'Orders Data'!$J$2:$J$161,"Completed") -> 7830 | D67: =B67-C67 -> 3150 | E67: =IF(B67=0,0,D67/B67) -> 0.28688525 | F67: =RANK(C67,$C$64:$C$68) -> 2 | H67: Total | I67: =SUM(I64:I66) -> 160 | J67: =SUM(J64:J66) -> 1 | K67: =SUM(K64:K66) -> 46500
A68: Pune | B68: =SUMIFS('Orders Data'!$K$2:$K$161,'Orders Data'!$I$2:$I$161,A68) -> 9910 | C68: =SUMIFS('Orders Data'!$K$2:$K$161,'Orders Data'!$I$2:$I$161,A68,'Orders Data'!$J$2:$J$161,"Completed") -> 8450 | D68: =B68-C68 -> 1460 | E68: =IF(B68=0,0,D68/B68) -> 0.14732593 | F68: =RANK(C68,$C$64:$C$68) -> 1
A69: Total | B69: =SUM(B64:B68) -> 46500 | C69: =SUM(C64:C68) -> 32990 | D69: =SUM(D64:D68) -> 13510 | E69: =IF(B69=0,0,D69/B69) -> 0.29053763
A70: =IF(AND(B69=$C$6,C69=$E$6),"✔ Totals match the Key Numbers above","✘ Totals do not match - check the data") -> ✔ Totals match the Key Numbers above
A71: Sales by product category | H71: Payment methods
A72: Category | B72: Total sales (all orders) | C72: Sales kept (Completed only) | D72: % of sales kept | H72: Payment method | I72: Valid orders | J72: Sales value | K72: Average per order
A73: Beverage | B73: =SUMIFS('Orders Data'!$K$2:$K$161,'Orders Data'!$E$2:$E$161,A73) -> 31160 | C73: =SUMIFS('Orders Data'!$K$2:$K$161,'Orders Data'!$E$2:$E$161,A73,'Orders Data'!$J$2:$J$161,"Completed") -> 22020 | D73: =IF(B73=0,0,C73/B73) -> 0.70667522 | H73: Card | I73: =COUNTIFS('Orders Data'!$H$2:$H$161,H73,'Orders Data'!$N$2:$N$161,"") -> 47 | J73: =SUMIFS('Orders Data'!$K$2:$K$161,'Orders Data'!$H$2:$H$161,H73) -> 14440 | K73: =IF(I73=0,0,J73/I73) -> 307.23404
A74: Bakery | B74: =SUMIFS('Orders Data'!$K$2:$K$161,'Orders Data'!$E$2:$E$161,A74) -> 8740 | C74: =SUMIFS('Orders Data'!$K$2:$K$161,'Orders Data'!$E$2:$E$161,A74,'Orders Data'!$J$2:$J$161,"Completed") -> 5910 | D74: =IF(B74=0,0,C74/B74) -> 0.67620137 | H74: Cash | I74: =COUNTIFS('Orders Data'!$H$2:$H$161,H74,'Orders Data'!$N$2:$N$161,"") -> 42 | J74: =SUMIFS('Orders Data'!$K$2:$K$161,'Orders Data'!$H$2:$H$161,H74) -> 15850 | K74: =IF(I74=0,0,J74/I74) -> 377.38095
A75: Food | B75: =SUMIFS('Orders Data'!$K$2:$K$161,'Orders Data'!$E$2:$E$161,A75) -> 6600 | C75: =SUMIFS('Orders Data'!$K$2:$K$161,'Orders Data'!$E$2:$E$161,A75,'Orders Data'!$J$2:$J$161,"Completed") -> 5060 | D75: =IF(B75=0,0,C75/B75) -> 0.76666667 | H75: UPI | I75: =COUNTIFS('Orders Data'!$H$2:$H$161,H75,'Orders Data'!$N$2:$N$161,"") -> 50 | J75: =SUMIFS('Orders Data'!$K$2:$K$161,'Orders Data'!$H$2:$H$161,H75) -> 16210 | K75: =IF(I75=0,0,J75/I75) -> 324.2
A76: Total | B76: =SUM(B73:B75) -> 46500 | C76: =SUM(C73:C75) -> 32990 | D76: =IF(B76=0,0,C76/B76) -> 0.70946237 | H76: Total | I76: =SUM(I73:I75) -> 139 | J76: =SUM(J73:J75) -> 46500
H77: "Valid orders" leaves out orders with a missing or invalid quantity or price.
A79: HOW THE DATA WAS CLEANED AND HOW TO READ IT
A80: • 10 duplicate orders were removed (170 rows became 160 unique orders).
A81: • City, customer and status had spelling, spacing and capital-letter mistakes (for example " mumbai", "DELHI ", "refunded "). These were fixed with formulas. The original entries are kept in the grey columns on the Orders Data sheet.
A82: ="• "&COUNTIF('Orders Data'!$N$2:$N$161,"?*")&" orders had a missing or invalid quantity or price. They stay in the data but count as ₹0 sales and are highlighted red on the Orders Data sheet." -> • 21 orders had a missing or invalid quantity or price. They stay in the data but count as ₹0 sales and are highlighted red on the Orders Data sheet.
A83: • Sales value = Quantity × Price. "Completed" orders are sales the café kept. "Cancelled" and "Refunded" orders are money that did not stay with the café.
A84: • The sheet "City x Status" shows the same sales split by city and status, like a pivot table, but it updates automatically.

Sheet Orders Data
A1: Order ID | B1: Date | C1: Customer | D1: Product | E1: Category | F1: Quantity | G1: Price (₹) | H1: Payment Method | I1: City | J1: Order Status | K1: Sales Value (₹) | L1: Order Size | M1: Counted as a Sale? | N1: Data Issue | P1: Customer (as entered) | Q1: City (as entered) | R1: Status (as entered) | T1: HOW TO READ THIS SHEET
A2: ORD2001 | B2: 46102 | C2: =TRIM(PROPER(P2)) -> Aditya Joshi | D2: Muffin | E2: Bakery | F2: 4 | G2: 110 | H2: UPI | I2: =TRIM(PROPER(Q2)) -> Chennai | J2: =TRIM(PROPER(R2)) -> Refunded | K2: =IF(N2="",F2*G2,0) -> 440 | L2: =IF(N2<>"","",IF(F2>=3,"Bulk (3+ items)","Regular")) -> Bulk (3+ items) | M2: =IF(J2="Completed","Yes","No") -> No | N2: =IF(F2="","Quantity missing",IF(F2<=0,"Quantity invalid",IF(G2="","Price missing",""))) | P2: Aditya Joshi | Q2: Chennai | R2: refunded | T2: Blue headers = data as recorded by the café.
A3: ORD2002 | B3: 46107 | C3: =TRIM(PROPER(P3)) -> Rohit Sharma | D3: Muffin | E3: Bakery | F3: 1 | G3: 110 | H3: UPI | I3: =TRIM(PROPER(Q3)) -> Mumbai | J3: =TRIM(PROPER(R3)) -> Cancelled | K3: =IF(N3="",F3*G3,0) -> 110 | L3: =IF(N3<>"","",IF(F3>=3,"Bulk (3+ items)","Regular")) -> Regular | M3: =IF(J3="Completed","Yes","No") -> No | N3: =IF(F3="","Quantity missing",IF(F3<=0,"Quantity invalid",IF(G3="","Price missing",""))) | P3: rohit sharma | Q3: mumbai | R3: cancelled | T3: Green headers = cleaned or calculated by formula.
A4: ORD2003 | B4: 46098 | C4: =TRIM(PROPER(P4)) -> Naina Bose | D4: Espresso | E4: Beverage | F4: 4 | G4: 120 | H4: Cash | I4: =TRIM(PROPER(Q4)) -> Chennai | J4: =TRIM(PROPER(R4)) -> Refunded | K4: =IF(N4="",F4*G4,0) -> 480 | L4: =IF(N4<>"","",IF(F4>=3,"Bulk (3+ items)","Regular")) -> Bulk (3+ items) | M4: =IF(J4="Completed","Yes","No") -> No | N4: =IF(F4="","Quantity missing",IF(F4<=0,"Quantity invalid",IF(G4="","Price missing",""))) | P4: Naina Bose | Q4: Chennai | R4: Refunded | T4: Grey columns (P:R) = the original messy entries, kept for reference.
A5: ORD2004 | B5: 46098 | C5: =TRIM(PROPER(P5)) -> Ira Menon | D5: Sandwich | E5: Food | F5: 1 | H5: Cash | I5: =TRIM(PROPER(Q5)) -> Bengaluru | J5: =TRIM(PROPER(R5)) -> Completed | K5: =IF(N5="",F5*G5,0) -> 0 | L5: =IF(N5<>"","",IF(F5>=3,"Bulk (3+ items)","Regular")) | M5: =IF(J5="Completed","Yes","No") -> Yes | N5: =IF(F5="","Quantity missing",IF(F5<=0,"Quantity invalid",IF(G5="","Price missing",""))) -> Price missing | P5: Ira Menon | Q5: Bengaluru | R5: Completed | T5: Red rows = orders with a missing or invalid quantity/price (counted as ₹0 sales).
A6: ORD2005 | B6: 46106 | C6: =TRIM(PROPER(P6)) -> Om Prakash | D6: Latte | E6: Beverage | F6: 0 | G6: 190 | H6: UPI | I6: =TRIM(PROPER(Q6)) -> Bengaluru | J6: =TRIM(PROPER(R6)) -> Completed | K6: =IF(N6="",F6*G6,0) -> 0 | L6: =IF(N6<>"","",IF(F6>=3,"Bulk (3+ items)","Regular")) | M6: =IF(J6="Completed","Yes","No") -> Yes | N6: =IF(F6="","Quantity missing",IF(F6<=0,"Quantity invalid",IF(G6="","Price missing",""))) -> Quantity invalid | P6: Om Prakash | Q6: Bengaluru | R6: Completed
A7: ORD2006 | B7: 46110 | C7: =TRIM(PROPER(P7)) -> Trisha Reddy | D7: Sandwich | E7: Food | F7: 1 | G7: 220 | H7: UPI | I7: =TRIM(PROPER(Q7)) -> Delhi | J7: =TRIM(PROPER(R7)) -> Refunded | K7: =IF(N7="",F7*G7,0) -> 220 | L7: =IF(N7<>"","",IF(F7>=3,"Bulk (3+ items)","Regular")) -> Regular | M7: =IF(J7="Completed","Yes","No") -> No | N7: =IF(F7="","Quantity missing",IF(F7<=0,"Quantity invalid",IF(G7="","Price missing",""))) | P7: Trisha Reddy | Q7: Delhi | R7: refunded
A8: ORD2007 | B8: 46098 | C8: =TRIM(PROPER(P8)) -> Simran Kaur | D8: Iced Tea | E8: Beverage | F8: 1 | G8: 160 | H8: Cash | I8: =TRIM(PROPER(Q8)) -> Delhi | J8: =TRIM(PROPER(R8)) -> Completed | K8: =IF(N8="",F8*G8,0) -> 160 | L8: =IF(N8<>"","",IF(F8>=3,"Bulk (3+ items)","Regular")) -> Regular | M8: =IF(J8="Completed","Yes","No") -> Yes | N8: =IF(F8="","Quantity missing",IF(F8<=0,"Quantity invalid",IF(G8="","Price missing",""))) | P8: Simran Kaur | Q8: Delhi | R8: Completed
A9: ORD2008 | B9: 46097 | C9: =TRIM(PROPER(P9)) -> Kunal Verma | D9: Espresso | E9: Beverage | F9: 4 | G9: 120 | H9: Card | I9: =TRIM(PROPER(Q9)) -> Bengaluru | J9: =TRIM(PROPER(R9)) -> Completed | K9: =IF(N9="",F9*G9,0) -> 480 | L9: =IF(N9<>"","",IF(F9>=3,"Bulk (3+ items)","Regular")) -> Bulk (3+ items) | M9: =IF(J9="Completed","Yes","No") -> Yes | N9: =IF(F9="","Quantity missing",IF(F9<=0,"Quantity invalid",IF(G9="","Price missing",""))) | P9: Kunal Verma | Q9: Bengaluru | R9: Completed
A10: ORD2009 | B10: 46098 | C10: =TRIM(PROPER(P10)) -> Ananya Iyer | D10: Croissant | E10: Bakery | F10: 1 | G10: 140 | H10: Card | I10: =TRIM(PROPER(Q10)) -> Mumbai | J10: =TRIM(PROPER(R10)) -> Completed | K10: =IF(N10="",F10*G10,0) -> 140 | L10: =IF(N10<>"","",IF(F10>=3,"Bulk (3+ items)","Regular")) -> Regular | M10: =IF(J10="Completed","Yes","No") -> Yes | N10: =IF(F10="","Quantity missing",IF(F10<=0,"Quantity invalid",IF(G10="","Price missing",""))) | P10: Ananya Iyer | Q10: Mumbai | R10: Completed
A11: ORD2010 | B11: 46100 | C11: =TRIM(PROPER(P11)) -> Kunal Verma | D11: Sandwich | E11: Food | F11: 3 | G11: 220 | H11: UPI | I11: =TRIM(PROPER(Q11)) -> Bengaluru | J11: =TRIM(PROPER(R11)) -> Completed | K11: =IF(N11="",F11*G11,0) -> 660 | L11: =IF(N11<>"","",IF(F11>=3,"Bulk (3+ items)","Regular")) -> Bulk (3+ items) | M11: =IF(J11="Completed","Yes","No") -> Yes | N11: =IF(F11="","Quantity missing",IF(F11<=0,"Quantity invalid",IF(G11="","Price missing",""))) | P11: Kunal Verma | Q11: Bengaluru | R11: Completed
A12: ORD2011 | B12: 46097 | C12: =TRIM(PROPER(P12)) -> Meher Dutta | D12: Muffin | E12: Bakery | G12: 110 | H12: Cash | I12: =TRIM(PROPER(Q12)) -> Pune | J12: =TRIM(PROPER(R12)) -> Refunded | K12: =IF(N12="",F12*G12,0) -> 0 | L12: =IF(N12<>"","",IF(F12>=3,"Bulk (3+ items)","Regular")) | M12: =IF(J12="Completed","Yes","No") -> No | N12: =IF(F12="","Quantity missing",IF(F12<=0,"Quantity invalid",IF(G12="","Price missing",""))) -> Quantity missing | P12: Meher Dutta | Q12: pune | R12: Refunded
A13: ORD2012 | B13: 46090 | C13: =TRIM(PROPER(P13)) -> Ritika Shah | D13: Cold Brew | E13: Beverage | F13: 3 | G13: 210 | H13: UPI | I13: =TRIM(PROPER(Q13)) -> Pune | J13: =TRIM(PROPER(R13)) -> Completed | K13: =IF(N13="",F13*G13,0) -> 630 | L13: =IF(N13<>"","",IF(F13>=3,"Bulk (3+ items)","Regular")) -> Bulk (3+ items) | M13: =IF(J13="Completed","Yes","No") -> Yes | N13: =IF(F13="","Quantity missing",IF(F13<=0,"Quantity invalid",IF(G13="","Price missing",""))) | P13: Ritika Shah | Q13: Pune | R13: Completed
A14: ORD2013 | B14: 46089 | C14: =TRIM(PROPER(P14)) -> Fahad Khan | D14: Latte | E14: Beverage | F14: 2 | G14: 190 | H14: Card | I14: =TRIM(PROPER(Q14)) -> Mumbai | J14: =TRIM(PROPER(R14)) -> Refunded | K14: =IF(N14="",F14*G14,0) -> 380 | L14: =IF(N14<>"","",IF(F14>=3,"Bulk (3+ items)","Regular")) -> Regular | M14: =IF(J14="Completed","Yes","No") -> No | N14: =IF(F14="","Quantity missing",IF(F14<=0,"Quantity invalid",IF(G14="","Price missing",""))) | P14: Fahad Khan | Q14: Mumbai | R14: Refunded
A15: ORD2014 | B15: 46101 | C15: =TRIM(PROPER(P15)) -> Simran Kaur | D15: Muffin | E15: Bakery | H15: Cash | I15: =TRIM(PROPER(Q15)) -> Bengaluru | J15: =TRIM(PROPER(R15)) -> Refunded | K15: =IF(N15="",F15*G15,0) -> 0 | L15: =IF(N15<>"","",IF(F15>=3,"Bulk (3+ items)","Regular")) | M15: =IF(J15="Completed","Yes","No") -> No | N15: =IF(F15="","Quantity missing",IF(F15<=0,"Quantity invalid",IF(G15="","Price missing",""))) -> Quantity missing | P15: simran kaur | Q15: Bengaluru | R15: REFUNDED
A16: ORD2015 | B16: 46096 | C16: =TRIM(PROPER(P16)) -> Om Prakash | D16: Espresso | E16: Beverage | F16: 1 | G16: 120 | H16: Card | I16: =TRIM(PROPER(Q16)) -> Mumbai | J16: =TRIM(PROPER(R16)) -> Refunded | K16: =IF(N16="",F16*G16,0) -> 120 | L16: =IF(N16<>"","",IF(F16>=3,"Bulk (3+ items)","Regular")) -> Regular | M16: =IF(J16="Completed","Yes","No") -> No | N16: =IF(F16="","Quantity missing",IF(F16<=0,"Quantity invalid",IF(G16="","Price missing",""))) | P16: Om Prakash | Q16: MUMBAI | R16: Refunded
A17: ORD2016 | B17: 46105 | C17: =TRIM(PROPER(P17)) -> Ira Menon | D17: Cappuccino | E17: Beverage | F17: 3 | G17: 180 | H17: UPI | I17: =TRIM(PROPER(Q17)) -> Pune | J17: =TRIM(PROPER(R17)) -> Completed | K17: =IF(N17="",F17*G17,0) -> 540 | L17: =IF(N17<>"","",IF(F17>=3,"Bulk (3+ items)","Regular")) -> Bulk (3+ items) | M17: =IF(J17="Completed","Yes","No") -> Yes | N17: =IF(F17="","Quantity missing",IF(F17<=0,"Quantity invalid",IF(G17="","Price missing",""))) | P17: Ira Menon | Q17: PUNE | R17: Completed
A18: ORD2017 | B18: 46110 | C18: =TRIM(PROPER(P18)) -> Aditya Joshi | D18: Latte | E18: Beverage | F18: 3 | G18: 190 | H18: Cash | I18: =TRIM(PROPER(Q18)) -> Mumbai | J18: =TRIM(PROPER(R18)) -> Refunded | K18: =IF(N18="",F18*G18,0) -> 570 | L18: =IF(N18<>"","",IF(F18>=3,"Bulk (3+ items)","Regular")) -> Bulk (3+ items) | M18: =IF(J18="Completed","Yes","No") -> No | N18: =IF(F18="","Quantity missing",IF(F18<=0,"Quantity invalid",IF(G18="","Price missing",""))) | P18: Aditya Joshi | Q18: Mumbai | R18: REFUNDED
A19: ORD2018 | B19: 46084 | C19: =TRIM(PROPER(P19)) -> Ananya Iyer | D19: Cappuccino | E19: Beverage | F19: 2 | G19: 180 | H19: Cash | I19: =TRIM(PROPER(Q19)) -> Bengaluru | J19: =TRIM(PROPER(R19)) -> Completed | K19: =IF(N19="",F19*G19,0) -> 360 | L19: =IF(N19<>"","",IF(F19>=3,"Bulk (3+ items)","Regular")) -> Regular | M19: =IF(J19="Completed","Yes","No") -> Yes | N19: =IF(F19="","Quantity missing",IF(F19<=0,"Quantity invalid",IF(G19="","Price missing",""))) | P19: Ananya Iyer | Q19: bengaluru | R19: Completed
A20: ORD2019 | B20: 46084 | C20: =TRIM(PROPER(P20)) -> Om Prakash | D20: Muffin | E20: Bakery | F20: 2 | G20: 110 | H20: Cash | I20: =TRIM(PROPER(Q20)) -> Delhi | J20: =TRIM(PROPER(R20)) -> Cancelled | K20: =IF(N20="",F20*G20,0) -> 220 | L20: =IF(N20<>"","",IF(F20>=3,"Bulk (3+ items)","Regular")) -> Regular | M20: =IF(J20="Completed","Yes","No") -> No | N20: =IF(F20="","Quantity missing",IF(F20<=0,"Quantity invalid",IF(G20="","Price missing",""))) | P20: Om Prakash | Q20: delhi | R20: Cancelled
A21: ORD2020 | B21: 46111 | C21: =TRIM(PROPER(P21)) -> Devansh Rao | D21: Brownie | E21: Bakery | F21: 3 | G21: 150 | H21: Card | I21: =TRIM(PROPER(Q21)) -> Chennai | J21: =TRIM(PROPER(R21)) -> Completed | K21: =IF(N21="",F21*G21,0) -> 450 | L21: =IF(N21<>"","",IF(F21>=3,"Bulk (3+ items)","Regular")) -> Bulk (3+ items) | M21: =IF(J21="Completed","Yes","No") -> Yes | N21: =IF(F21="","Quantity missing",IF(F21<=0,"Quantity invalid",IF(G21="","Price missing",""))) | P21: Devansh Rao | Q21: Chennai | R21: Completed
A22: ORD2021 | B22: 46083 | C22: =TRIM(PROPER(P22)) -> Ananya Iyer | D22: Espresso | E22: Beverage | F22: 1 | G22: 120 | H22: UPI | I22: =TRIM(PROPER(Q22)) -> Delhi | J22: =TRIM(PROPER(R22)) -> Completed | K22: =IF(N22="",F22*G22,0) -> 120 | L22: =IF(N22<>"","",IF(F22>=3,"Bulk (3+ items)","Regular")) -> Regular | M22: =IF(J22="Completed","Yes","No") -> Yes | N22: =IF(F22="","Quantity missing",IF(F22<=0,"Quantity invalid",IF(G22="","Price missing",""))) | P22: Ananya Iyer | Q22: DELHI | R22: completed
A23: ORD2022 | B23: 46110 | C23: =TRIM(PROPER(P23)) -> Naina Bose | D23: Iced Tea | E23: Beverage | F23: 1 | G23: 160 | H23: UPI | I23: =TRIM(PROPER(Q23)) -> Delhi | J23: =TRIM(PROPER(R23)) -> Completed | K23: =IF(N23="",F23*G23,0) -> 160 | L23: =IF(N23<>"","",IF(F23>=3,"Bulk (3+ items)","Regular")) -> Regular | M23: =IF(J23="Completed","Yes","No") -> Yes | N23: =IF(F23="","Quantity missing",IF(F23<=0,"Quantity invalid",IF(G23="","Price missing",""))) | P23: naina bose | Q23: Delhi | R23: COMPLETED
A24: ORD2023 | B24: 46082 | C24: =TRIM(PROPER(P24)) -> Rohit Sharma | D24: Cappuccino | E24: Beverage | F24: 1 | G24: 180 | H24: UPI | I24: =TRIM(PROPER(Q24)) -> Mumbai | J24: =TRIM(PROPER(R24)) -> Completed | K24: =IF(N24="",F24*G24,0) -> 180 | L24: =IF(N24<>"","",IF(F24>=3,"Bulk (3+ items)","Regular")) -> Regular | M24: =IF(J24="Completed","Yes","No") -> Yes | N24: =IF(F24="","Quantity missing",IF(F24<=0,"Quantity invalid",IF(G24="","Price missing",""))) | P24: Rohit Sharma | Q24: mumbai | R24: completed
A25: ORD2024 | B25: 46093 | C25: =TRIM(PROPER(P25)) -> Simran Kaur | D25: Muffin | E25: Bakery | F25: 3 | G25: 110 | H25: UPI | I25: =TRIM(PROPER(Q25)) -> Pune | J25: =TRIM(PROPER(R25)) -> Completed | K25: =IF(N25="",F25*G25,0) -> 330 | L25: =IF(N25<>"","",IF(F25>=3,"Bulk (3+ items)","Regular")) -> Bulk (3+ items) | M25: =IF(J25="Completed","Yes","No") -> Yes | N25: =IF(F25="","Quantity missing",IF(F25<=0,"Quantity invalid",IF(G25="","Price missing",""))) | P25: Simran Kaur | Q25: Pune | R25: Completed
A26: ORD2025 | B26: 46099 | C26: =TRIM(PROPER(P26)) -> Simran Kaur | D26: Espresso | E26: Beverage | F26: 1 | G26: 120 | H26: UPI | I26: =TRIM(PROPER(Q26)) -> Pune | J26: =TRIM(PROPER(R26)) -> Completed | K26: =IF(N26="",F26*G26,0) -> 120 | L26: =IF(N26<>"","",IF(F26>=3,"Bulk (3+ items)","Regular")) -> Regular | M26: =IF(J26="Completed","Yes","No") -> Yes | N26: =IF(F26="","Quantity missing",IF(F26<=0,"Quantity invalid",IF(G26="","Price missing",""))) | P26: Simran Kaur | Q26: Pune | R26: completed
A27: ORD2026 | B27: 46109 | C27: =TRIM(PROPER(P27)) -> Trisha Reddy | D27: Muffin | E27: Bakery | F27: 1 | G27: 110 | H27: UPI | I27: =TRIM(PROPER(Q27)) -> Pune | J27: =TRIM(PROPER(R27)) -> Cancelled | K27: =IF(N27="",F27*G27,0) -> 110 | L27: =IF(N27<>"","",IF(F27>=3,"Bulk (3+ items)","Regular")) -> Regular | M27: =IF(J27="Completed","Yes","No") -> No | N27: =IF(F27="","Quantity missing",IF(F27<=0,"Quantity invalid",IF(G27="","Price missing",""))) | P27: Trisha Reddy | Q27: pune | R27: Cancelled
... A50: ORD2050 | B50: 46084 | C50: =TRIM(PROPER(P50)) -> Om Prakash | D50: Brownie | E50: Bakery | F50: 1 | G50: 150 | H50: UPI | I50: =TRIM(PROPER(Q50)) -> Mumbai | J50: =TRIM(PROPER(R50)) -> Completed | K50: =IF(N50="",F50*G50,0) -> 150 | L50: =IF(N50<>"","",IF(F50>=3,"Bulk (3+ items)","Regular")) -> Regular | M50: =IF(J50="Completed","Yes","No") -> Yes | N50: =IF(F50="","Quantity missing",IF(F50<=0,"Quantity invalid",IF(G50="","Price missing",""))) | P50: Om Prakash | Q50: Mumbai | R50: Completed
A51: ORD2051 | B51: 46098 | C51: =TRIM(PROPER(P51)) -> Trisha Reddy | D51: Latte | E51: Beverage | F51: 1 | H51: Card | I51: =TRIM(PROPER(Q51)) -> Delhi | J51: =TRIM(PROPER(R51)) -> Completed | K51: =IF(N51="",F51*G51,0) -> 0 | L51: =IF(N51<>"","",IF(F51>=3,"Bulk (3+ items)","Regular")) | M51: =IF(J51="Completed","Yes","No") -> Yes | N51: =IF(F51="","Quantity missing",IF(F51<=0,"Quantity invalid",IF(G51="","Price missing",""))) -> Price missing | P51: Trisha Reddy | Q51: delhi | R51: Completed
A52: ORD2052 | B52: 46097 | C52: =TRIM(PROPER(P52)) -> Om Prakash | D52: Hot Chocolate | E52: Beverage | F52: 4 | G52: 200 | H52: Cash | I52: =TRIM(PROPER(Q52)) -> Pune | J52: =TRIM(PROPER(R52)) -> Completed | K52: =IF(N52="",F52*G52,0) -> 800 | L52: =IF(N52<>"","",IF(F52>=3,"Bulk (3+ items)","Regular")) -> Bulk (3+ items) | M52: =IF(J52="Completed","Yes","No") -> Yes | N52: =IF(F52="","Quantity missing",IF(F52<=0,"Quantity invalid",IF(G52="","Price missing",""))) | P52: Om Prakash | Q52: PUNE | R52: Completed
A53: ORD2053 | B53: 46093 | C53: =TRIM(PROPER(P53)) -> Fahad Khan | D53: Espresso | E53: Beverage | F53: 1 | G53: 120 | H53: Card | I53: =TRIM(PROPER(Q53)) -> Mumbai | J53: =TRIM(PROPER(R53)) -> Completed | K53: =IF(N53="",F53*G53,0) -> 120 | L53: =IF(N53<>"","",IF(F53>=3,"Bulk (3+ items)","Regular")) -> Regular | M53: =IF(J53="Completed","Yes","No") -> Yes | N53: =IF(F53="","Quantity missing",IF(F53<=0,"Quantity invalid",IF(G53="","Price missing",""))) | P53: fahad khan | Q53: MUMBAI | R53: Completed
A54: ORD2054 | B54: 46108 | C54: =TRIM(PROPER(P54)) -> Trisha Reddy | D54: Cold Brew | E54: Beverage | F54: 4 | G54: 210 | H54: Card | I54: =TRIM(PROPER(Q54)) -> Bengaluru | J54: =TRIM(PROPER(R54)) -> Completed | K54: =IF(N54="",F54*G54,0) -> 840 | L54: =IF(N54<>"","",IF(F54>=3,"Bulk (3+ items)","Regular")) -> Bulk (3+ items) | M54: =IF(J54="Completed","Yes","No") -> Yes | N54: =IF(F54="","Quantity missing",IF(F54<=0,"Quantity invalid",IF(G54="","Price missing",""))) | P54: Trisha Reddy | Q54: Bengaluru | R54: Completed
A55: ORD2055 | B55: 46086 | C55: =TRIM(PROPER(P55)) -> Devansh Rao | D55: Latte | E55: Beverage | F55: 3 | G55: 190 | H55: Cash | I55: =TRIM(PROPER(Q55)) -> Pune | J55: =TRIM(PROPER(R55)) -> Completed | K55: =IF(N55="",F55*G55,0) -> 570 | L55: =IF(N55<>"","",IF(F55>=3,"Bulk (3+ items)","Regular")) -> Bulk (3+ items) | M55: =IF(J55="Completed","Yes","No") -> Yes | N55: =IF(F55="","Quantity missing",IF(F55<=0,"Quantity invalid",IF(G55="","Price missing",""))) | P55: Devansh Rao | Q55: PUNE | R55: completed
A56: ORD2056 | B56: 46110 | C56: =TRIM(PROPER(P56)) -> Tushar Gill | D56: Cold Brew | E56: Beverage | F56: 1 | G56: 210 | H56: Cash | I56: =TRIM(PROPER(Q56)) -> Mumbai | J56: =TRIM(PROPER(R56)) -> Completed | K56: =IF(N56="",F56*G56,0) -> 210 | L56: =IF(N56<>"","",IF(F56>=3,"Bulk (3+ items)","Regular")) -> Regular | M56: =IF(J56="Completed","Yes","No") -> Yes | N56: =IF(F56="","Quantity missing",IF(F56<=0,"Quantity invalid",IF(G56="","Price missing",""))) | P56: Tushar Gill | Q56: Mumbai | R56: Completed
A57: ORD2057 | B57: 46097 | C57: =TRIM(PROPER(P57)) -> Ira Menon | D57: Hot Chocolate | E57: Beverage | F57: 4 | G57: 200 | H57: Cash | I57: =TRIM(PROPER(Q57)) -> Pune | J57: =TRIM(PROPER(R57)) -> Completed | K57: =IF(N57="",F57*G57,0) -> 800 | L57: =IF(N57<>"","",IF(F57>=3,"Bulk (3+ items)","Regular")) -> Bulk (3+ items) | M57: =IF(J57="Completed","Yes","No") -> Yes | N57: =IF(F57="","Quantity missing",IF(F57<=0,"Quantity invalid",IF(G57="","Price missing",""))) | P57: ira menon | Q57: PUNE | R57: Completed
A58: ORD2058 | B58: 46110 | C58: =TRIM(PROPER(P58)) -> Om Prakash | D58: Muffin | E58: Bakery | F58: 1 | G58: 110 | H58: UPI | I58: =TRIM(PROPER(Q58)) -> Chennai | J58: =TRIM(PROPER(R58)) -> Refunded | K58: =IF(N58="",F58*G58,0) -> 110 | L58: =IF(N58<>"","",IF(F58>=3,"Bulk (3+ items)","Regular")) -> Regular | M58: =IF(J58="Completed","Yes","No") -> No | N58: =IF(F58="","Quantity missing",IF(F58<=0,"Quantity invalid",IF(G58="","Price missing",""))) | P58: Om Prakash | Q58: chennai | R58: Refunded
A59: ORD2059 | B59: 46087 | C59: =TRIM(PROPER(P59)) -> Devansh Rao | D59: Iced Tea | E59: Beverage | G59: 160 | H59: UPI | I59: =TRIM(PROPER(Q59)) -> Bengaluru | J59: =TRIM(PROPER(R59)) -> Completed | K59: =IF(N59="",F59*G59,0) -> 0 | L59: =IF(N59<>"","",IF(F59>=3,"Bulk (3+ items)","Regular")) | M59: =IF(J59="Completed","Yes","No") -> Yes | N59: =IF(F59="","Quantity missing",IF(F59<=0,"Quantity invalid",IF(G59="","Price missing",""))) -> Quantity missing | P59: Devansh Rao | Q59: bengaluru | R59: Completed
A60: ORD2060 | B60: 46097 | C60: =TRIM(PROPER(P60)) -> Naina Bose | D60: Cold Brew | E60: Beverage | F60: 2 | G60: 210 | H60: UPI | I60: =TRIM(PROPER(Q60)) -> Bengaluru | J60: =TRIM(PROPER(R60)) -> Completed | K60: =IF(N60="",F60*G60,0) -> 420 | L60: =IF(N60<>"","",IF(F60>=3,"Bulk (3+ items)","Regular")) -> Regular | M60: =IF(J60="Completed","Yes","No") -> Yes | N60: =IF(F60="","Quantity missing",IF(F60<=0,"Quantity invalid",IF(G60="","Price missing",""))) | P60: Naina Bose | Q60: Bengaluru | R60: Completed
A61: ORD2061 | B61: 46107 | C61: =TRIM(PROPER(P61)) -> Naina Bose | D61: Cappuccino | E61: Beverage | F61: 2 | G61: 180 | H61: Cash | I61: =TRIM(PROPER(Q61)) -> Delhi | J61: =TRIM(PROPER(R61)) -> Completed | K61: =IF(N61="",F61*G61,0) -> 360 | L61: =IF(N61<>"","",IF(F61>=3,"Bulk (3+ items)","Regular")) -> Regular | M61: =IF(J61="Completed","Yes","No") -> Yes | N61: =IF(F61="","Quantity missing",IF(F61<=0,"Quantity invalid",IF(G61="","Price missing",""))) | P61: naina bose | Q61: Delhi | R61: Completed
A62: ORD2062 | B62: 46096 | C62: =TRIM(PROPER(P62)) -> Aditya Joshi | D62: Muffin | E62: Bakery | F62: 1 | G62: 110 | H62: UPI | I62: =TRIM(PROPER(Q62)) -> Mumbai | J62: =TRIM(PROPER(R62)) -> Completed | K62: =IF(N62="",F62*G62,0) -> 110 | L62: =IF(N62<>"","",IF(F62>=3,"Bulk (3+ items)","Regular")) -> Regular | M62: =IF(J62="Completed","Yes","No") -> Yes | N62: =IF(F62="","Quantity missing",IF(F62<=0,"Quantity invalid",IF(G62="","Price missing",""))) | P62: Aditya Joshi | Q62: MUMBAI | R62: Completed
...

Sheet City x Status
A1: Sales by City and Order Status
A2: Sales value in rupees (₹). Works like a pivot table, but every number is a formula, so it updates automatically.
A4: City | B4: Cancelled | C4: Completed | D4: Refunded | E4: Grand total
A5: Bengaluru | B5: =SUMIFS('Orders Data'!$K$2:$K$161,'Orders Data'!$I$2:$I$161,$A5,'Orders Data'!$J$2:$J$161,B$4) -> 1060 | C5: =SUMIFS('Orders Data'!$K$2:$K$161,'Orders Data'!$I$2:$I$161,$A5,'Orders Data'!$J$2:$J$161,C$4) -> 7280 | D5: =SUMIFS('Orders Data'!$K$2:$K$161,'Orders Data'!$I$2:$I$161,$A5,'Orders Data'!$J$2:$J$161,D$4) -> 1760 | E5: =SUM(B5:D5) -> 10100
A6: Chennai | B6: =SUMIFS('Orders Data'!$K$2:$K$161,'Orders Data'!$I$2:$I$161,$A6,'Orders Data'!$J$2:$J$161,B$4) -> 1240 | C6: =SUMIFS('Orders Data'!$K$2:$K$161,'Orders Data'!$I$2:$I$161,$A6,'Orders Data'!$J$2:$J$161,C$4) -> 2600 | D6: =SUMIFS('Orders Data'!$K$2:$K$161,'Orders Data'!$I$2:$I$161,$A6,'Orders Data'!$J$2:$J$161,D$4) -> 2380 | E6: =SUM(B6:D6) -> 6220
A7: Delhi | B7: =SUMIFS('Orders Data'!$K$2:$K$161,'Orders Data'!$I$2:$I$161,$A7,'Orders Data'!$J$2:$J$161,B$4) -> 1520 | C7: =SUMIFS('Orders Data'!$K$2:$K$161,'Orders Data'!$I$2:$I$161,$A7,'Orders Data'!$J$2:$J$161,C$4) -> 6830 | D7: =SUMIFS('Orders Data'!$K$2:$K$161,'Orders Data'!$I$2:$I$161,$A7,'Orders Data'!$J$2:$J$161,D$4) -> 940 | E7: =SUM(B7:D7) -> 9290
A8: Mumbai | B8: =SUMIFS('Orders Data'!$K$2:$K$161,'Orders Data'!$I$2:$I$161,$A8,'Orders Data'!$J$2:$J$161,B$4) -> 1450 | C8: =SUMIFS('Orders Data'!$K$2:$K$161,'Orders Data'!$I$2:$I$161,$A8,'Orders Data'!$J$2:$J$161,C$4) -> 7830 | D8: =SUMIFS('Orders Data'!$K$2:$K$161,'Orders Data'!$I$2:$I$161,$A8,'Orders Data'!$J$2:$J$161,D$4) -> 1700 | E8: =SUM(B8:D8) -> 10980
A9: Pune | B9: =SUMIFS('Orders Data'!$K$2:$K$161,'Orders Data'!$I$2:$I$161,$A9,'Orders Data'!$J$2:$J$161,B$4) -> 1140 | C9: =SUMIFS('Orders Data'!$K$2:$K$161,'Orders Data'!$I$2:$I$161,$A9,'Orders Data'!$J$2:$J$161,C$4) -> 8450 | D9: =SUMIFS('Orders Data'!$K$2:$K$161,'Orders Data'!$I$2:$I$161,$A9,'Orders Data'!$J$2:$J$161,D$4) -> 320 | E9: =SUM(B9:D9) -> 9910
A10: Grand total | B10: =SUM(B5:B9) -> 6410 | C10: =SUM(C5:C9) -> 32990 | D10: =SUM(D5:D9) -> 7100 | E10: =SUM(E5:E9) -> 46500
A12: =IF(E10=Summary!$C$6,"✔ Grand total matches Total sales on the Summary sheet","✘ Grand total does not match the Summary sheet") -> ✔ Grand total matches Total sales on the Summary sheet
