Workbook

Sheet README
A1: Excel Skills Workbook
A2: Lookups, text and date functions, summary tables, a dashboard and a 20-question data analysis
A4: About | B4: A practice workbook where I worked through the Excel skills a data analyst uses every day. All data is simulated for practice. Every result in the workbook is a formula, so it updates if the data changes.
A5: Dashboard | B5: Six KPI cards, three insight lines and four charts for 300 sales orders. The category dropdown (yellow cell) filters the KPIs and charts, much like a slicer.
A6: Pivot Summary | B6: Revenue by region, category × region, month and salesperson, with profit, orders, averages and % of total. Built with SUMIFS, COUNTIFS and SUMPRODUCT, with a check that every table matches the source total. The Pivot Data sheet is laid out so a native PivotTable can be inserted straight from it.
A7: Lookups | B7: Product lookups, order pricing with a "Not found" fallback, and commission slabs with approximate match. The grey text shows the XLOOKUP version; the live cells use INDEX/MATCH so they work in every Excel version.
A8: Text Functions | B8: Cleaning and splitting 8 messy records: TRIM, PROPER, LEFT, MID, RIGHT, FIND, VALUE and joining with &.
A9: Date Functions | B9: YEAR, MONTH, DAY, TEXT, EOMONTH, date differences and DATEDIF for age, using a fixed as-of date.
A10: Employee Analysis | B10: 20 questions on 40 employee records: SUMIFS, COUNTIFS, AVERAGEIF, lookups, text cleaning, dates, RANK, MEDIAN and unique counts.
A11: Data sheets | B11: Pivot Data (300 orders) and Employee Data (40 employees).
A12: Skills | B12: SUM / AVERAGE / COUNT, SUMIFS / COUNTIFS / AVERAGEIF, XLOOKUP and INDEX/MATCH, IF / IFERROR, TRIM / PROPER / LEFT / MID / RIGHT / FIND, DATE functions, SUMPRODUCT, RANK, data validation, conditional summaries and charts.

Sheet Dashboard
A1: Sales Dashboard 2025
A2: 300 simulated orders across four regions, four categories and eight salespeople. Amounts in rupees (₹).
A4: Category | C4: All | E4: Select a category to update the KPIs and charts
A6: Revenue | C6: Profit | E6: Profit margin | G6: Orders | I6: Avg. order value | K6: Units sold
A7: =SUMIFS('Pivot Data'!$G$2:$G$301,'Pivot Data'!$D$2:$D$301,$B$52) -> 3174770 | C7: =A7-SUMIFS('Pivot Data'!$H$2:$H$301,'Pivot Data'!$D$2:$D$301,$B$52) -> 1075060 | E7: =IF(A7=0,0,C7/A7) -> 0.33862611 | G7: =COUNTIFS('Pivot Data'!$D$2:$D$301,$B$52) -> 300 | I7: =IF(G7=0,0,A7/G7) -> 10582.567 | K7: =SUMIFS('Pivot Data'!$F$2:$F$301,'Pivot Data'!$D$2:$D$301,$B$52) -> 1333
A9: KEY INSIGHTS
A10: ="• "&INDEX($A$66:$A$77,MATCH(MAX($B$66:$B$77),$B$66:$B$77,0))&" is the strongest month, with "&TEXT(MAX($B$66:$B$77),"₹#,##0")&" in revenue." -> • Jan is the strongest month, with ₹420,579 in revenue.
A11: ="• "&INDEX($A$56:$A$59,MATCH(MAX($B$56:$B$59),$B$56:$B$59,0))&" is the top region ("&TEXT(MAX($B$56:$B$59),"₹#,##0")&"), and "&INDEX($A$56:$A$59,MATCH(MAX($D$56:$D$59),$D$56:$D$59,0))&" has the best margin ("&TEXT(MAX($D$56:$D$59),"0%")&")." -> • East is the top region (₹973,504), and South has the best margin (34%).
A12: ="• "&INDEX($A$81:$A$88,MATCH(MAX($B$81:$B$88),$B$81:$B$88,0))&" is the top salesperson with "&TEXT(MAX($B$81:$B$88),"₹#,##0")&" in revenue." -> • Harsh is the top salesperson with ₹506,447 in revenue.
A50: Chart data (feeds the charts above)
A52: Category filter | B52: =IF($C$4="All","*",$C$4) -> *
A55: Region | B55: Revenue | C55: Profit | D55: Margin
A56: East | B56: =SUMIFS('Pivot Data'!$G$2:$G$301,'Pivot Data'!$C$2:$C$301,A56,'Pivot Data'!$D$2:$D$301,$B$52) -> 973504 | C56: =B56-SUMIFS('Pivot Data'!$H$2:$H$301,'Pivot Data'!$C$2:$C$301,A56,'Pivot Data'!$D$2:$D$301,$B$52) -> 335608 | D56: =IF(B56=0,0,C56/B56) -> 0.34474229
A57: North | B57: =SUMIFS('Pivot Data'!$G$2:$G$301,'Pivot Data'!$C$2:$C$301,A57,'Pivot Data'!$D$2:$D$301,$B$52) -> 815766 | C57: =B57-SUMIFS('Pivot Data'!$H$2:$H$301,'Pivot Data'!$C$2:$C$301,A57,'Pivot Data'!$D$2:$D$301,$B$52) -> 266932 | D57: =IF(B57=0,0,C57/B57) -> 0.32721638
A58: South | B58: =SUMIFS('Pivot Data'!$G$2:$G$301,'Pivot Data'!$C$2:$C$301,A58,'Pivot Data'!$D$2:$D$301,$B$52) -> 868983 | C58: =B58-SUMIFS('Pivot Data'!$H$2:$H$301,'Pivot Data'!$C$2:$C$301,A58,'Pivot Data'!$D$2:$D$301,$B$52) -> 299748 | D58: =IF(B58=0,0,C58/B58) -> 0.34494116
A59: West | B59: =SUMIFS('Pivot Data'!$G$2:$G$301,'Pivot Data'!$C$2:$C$301,A59,'Pivot Data'!$D$2:$D$301,$B$52) -> 516517 | C59: =B59-SUMIFS('Pivot Data'!$H$2:$H$301,'Pivot Data'!$C$2:$C$301,A59,'Pivot Data'!$D$2:$D$301,$B$52) -> 172772 | D59: =IF(B59=0,0,C59/B59) -> 0.33449431
A65: Month | B65: Revenue
A66: =TEXT(DATE(2025,1,1),"mmm") -> Jan | B66: =SUMPRODUCT((MONTH('Pivot Data'!$B$2:$B$301)=1)*((($C$4="All")+('Pivot Data'!$D$2:$D$301=$C$4))>0)*'Pivot Data'!$G$2:$G$301) -> 420579
A67: =TEXT(DATE(2025,2,1),"mmm") -> Feb | B67: =SUMPRODUCT((MONTH('Pivot Data'!$B$2:$B$301)=2)*((($C$4="All")+('Pivot Data'!$D$2:$D$301=$C$4))>0)*'Pivot Data'!$G$2:$G$301) -> 231035
A68: =TEXT(DATE(2025,3,1),"mmm") -> Mar | B68: =SUMPRODUCT((MONTH('Pivot Data'!$B$2:$B$301)=3)*((($C$4="All")+('Pivot Data'!$D$2:$D$301=$C$4))>0)*'Pivot Data'!$G$2:$G$301) -> 217972
A69: =TEXT(DATE(2025,4,1),"mmm") -> Apr | B69: =SUMPRODUCT((MONTH('Pivot Data'!$B$2:$B$301)=4)*((($C$4="All")+('Pivot Data'!$D$2:$D$301=$C$4))>0)*'Pivot Data'!$G$2:$G$301) -> 246620
A70: =TEXT(DATE(2025,5,1),"mmm") -> May | B70: =SUMPRODUCT((MONTH('Pivot Data'!$B$2:$B$301)=5)*((($C$4="All")+('Pivot Data'!$D$2:$D$301=$C$4))>0)*'Pivot Data'!$G$2:$G$301) -> 155695
A71: =TEXT(DATE(2025,6,1),"mmm") -> Jun | B71: =SUMPRODUCT((MONTH('Pivot Data'!$B$2:$B$301)=6)*((($C$4="All")+('Pivot Data'!$D$2:$D$301=$C$4))>0)*'Pivot Data'!$G$2:$G$301) -> 227916
A72: =TEXT(DATE(2025,7,1),"mmm") -> Jul | B72: =SUMPRODUCT((MONTH('Pivot Data'!$B$2:$B$301)=7)*((($C$4="All")+('Pivot Data'!$D$2:$D$301=$C$4))>0)*'Pivot Data'!$G$2:$G$301) -> 257182
A73: =TEXT(DATE(2025,8,1),"mmm") -> Aug | B73: =SUMPRODUCT((MONTH('Pivot Data'!$B$2:$B$301)=8)*((($C$4="All")+('Pivot Data'!$D$2:$D$301=$C$4))>0)*'Pivot Data'!$G$2:$G$301) -> 317784
A74: =TEXT(DATE(2025,9,1),"mmm") -> Sep | B74: =SUMPRODUCT((MONTH('Pivot Data'!$B$2:$B$301)=9)*((($C$4="All")+('Pivot Data'!$D$2:$D$301=$C$4))>0)*'Pivot Data'!$G$2:$G$301) -> 208938
A75: =TEXT(DATE(2025,10,1),"mmm") -> Oct | B75: =SUMPRODUCT((MONTH('Pivot Data'!$B$2:$B$301)=10)*((($C$4="All")+('Pivot Data'!$D$2:$D$301=$C$4))>0)*'Pivot Data'!$G$2:$G$301) -> 278922
A76: =TEXT(DATE(2025,11,1),"mmm") -> Nov | B76: =SUMPRODUCT((MONTH('Pivot Data'!$B$2:$B$301)=11)*((($C$4="All")+('Pivot Data'!$D$2:$D$301=$C$4))>0)*'Pivot Data'!$G$2:$G$301) -> 368091
A77: =TEXT(DATE(2025,12,1),"mmm") -> Dec | B77: =SUMPRODUCT((MONTH('Pivot Data'!$B$2:$B$301)=12)*((($C$4="All")+('Pivot Data'!$D$2:$D$301=$C$4))>0)*'Pivot Data'!$G$2:$G$301) -> 244036
A80: Salesperson | B80: Revenue
A81: Anita | B81: =SUMIFS('Pivot Data'!$G$2:$G$301,'Pivot Data'!$E$2:$E$301,A81,'Pivot Data'!$D$2:$D$301,$B$52) -> 354327
A82: Bharat | B82: =SUMIFS('Pivot Data'!$G$2:$G$301,'Pivot Data'!$E$2:$E$301,A82,'Pivot Data'!$D$2:$D$301,$B$52) -> 443986
A83: Chetan | B83: =SUMIFS('Pivot Data'!$G$2:$G$301,'Pivot Data'!$E$2:$E$301,A83,'Pivot Data'!$D$2:$D$301,$B$52) -> 259292
A84: Divya | B84: =SUMIFS('Pivot Data'!$G$2:$G$301,'Pivot Data'!$E$2:$E$301,A84,'Pivot Data'!$D$2:$D$301,$B$52) -> 469132
A85: Farhan | B85: =SUMIFS('Pivot Data'!$G$2:$G$301,'Pivot Data'!$E$2:$E$301,A85,'Pivot Data'!$D$2:$D$301,$B$52) -> 465415
A86: Gita | B86: =SUMIFS('Pivot Data'!$G$2:$G$301,'Pivot Data'!$E$2:$E$301,A86,'Pivot Data'!$D$2:$D$301,$B$52) -> 290308
A87: Harsh | B87: =SUMIFS('Pivot Data'!$G$2:$G$301,'Pivot Data'!$E$2:$E$301,A87,'Pivot Data'!$D$2:$D$301,$B$52) -> 506447
A88: Isha | B88: =SUMIFS('Pivot Data'!$G$2:$G$301,'Pivot Data'!$E$2:$E$301,A88,'Pivot Data'!$D$2:$D$301,$B$52) -> 385863

Sheet Pivot Summary
A1: Pivot summary
A2: Summary tables built with SUMIFS, COUNTIFS and SUMPRODUCT on the Pivot Data sheet. They update when the data changes.
A3: Revenue by region | I3: Quick answers
A4: Region | B4: Revenue | C4: Cost | D4: Profit | E4: Orders | F4: Avg revenue per order | G4: % of total revenue | I4: Question | J4: Answer
A5: East | B5: =SUMIFS('Pivot Data'!$G$2:$G$301,'Pivot Data'!$C$2:$C$301,A5) -> 973504 | C5: =SUMIFS('Pivot Data'!$H$2:$H$301,'Pivot Data'!$C$2:$C$301,A5) -> 637896 | D5: =B5-C5 -> 335608 | E5: =COUNTIFS('Pivot Data'!$C$2:$C$301,A5) -> 89 | F5: =B5/E5 -> 10938.247 | G5: =B5/$B$9 -> 0.30663765 | I5: Month with the highest revenue | J5: =INDEX(B21:B32,MATCH(MAX(C21:C32),C21:C32,0)) -> January
A6: North | B6: =SUMIFS('Pivot Data'!$G$2:$G$301,'Pivot Data'!$C$2:$C$301,A6) -> 815766 | C6: =SUMIFS('Pivot Data'!$H$2:$H$301,'Pivot Data'!$C$2:$C$301,A6) -> 548834 | D6: =B6-C6 -> 266932 | E6: =COUNTIFS('Pivot Data'!$C$2:$C$301,A6) -> 70 | F6: =B6/E6 -> 11653.8 | G6: =B6/$B$9 -> 0.25695279 | I6: Top salesperson by revenue | J6: =F37 -> Harsh
A7: South | B7: =SUMIFS('Pivot Data'!$G$2:$G$301,'Pivot Data'!$C$2:$C$301,A7) -> 868983 | C7: =SUMIFS('Pivot Data'!$H$2:$H$301,'Pivot Data'!$C$2:$C$301,A7) -> 569235 | D7: =B7-C7 -> 299748 | E7: =COUNTIFS('Pivot Data'!$C$2:$C$301,A7) -> 74 | F7: =B7/E7 -> 11743.014 | G7: =B7/$B$9 -> 0.27371526 | I7: West share of total revenue | J7: =G8 -> 0.16269431
A8: West | B8: =SUMIFS('Pivot Data'!$G$2:$G$301,'Pivot Data'!$C$2:$C$301,A8) -> 516517 | C8: =SUMIFS('Pivot Data'!$H$2:$H$301,'Pivot Data'!$C$2:$C$301,A8) -> 343745 | D8: =B8-C8 -> 172772 | E8: =COUNTIFS('Pivot Data'!$C$2:$C$301,A8) -> 67 | F8: =B8/E8 -> 7709.209 | G8: =B8/$B$9 -> 0.16269431 | I8: Total profit | J8: =D9 -> 1075060
A9: Grand total | B9: =SUM(B5:B8) -> 3174770 | C9: =SUM(C5:C8) -> 2099710 | D9: =SUM(D5:D8) -> 1075060 | E9: =SUM(E5:E8) -> 300 | F9: =B9/E9 -> 10582.567 | G9: =SUM(G5:G8) -> 1 | I9: Average revenue per East order | J9: =ROUND(F5,0) -> 10938
I10: Electronics revenue in South | J10: =D14 -> 293911
A11: Revenue by category and region
A12: Category | B12: East | C12: North | D12: South | E12: West | F12: Total | I12: =IF(AND(ROUND(B9-F17,0)=0,ROUND(B9-C33,0)=0,ROUND(B9-B45,0)=0),"✔ All tables match the Pivot Data total","✘ Totals do not match") -> ✔ All tables match the Pivot Data total
A13: Apparel | B13: =SUMIFS('Pivot Data'!$G$2:$G$301,'Pivot Data'!$D$2:$D$301,$A13,'Pivot Data'!$C$2:$C$301,B$12) -> 150059 | C13: =SUMIFS('Pivot Data'!$G$2:$G$301,'Pivot Data'!$D$2:$D$301,$A13,'Pivot Data'!$C$2:$C$301,C$12) -> 76885 | D13: =SUMIFS('Pivot Data'!$G$2:$G$301,'Pivot Data'!$D$2:$D$301,$A13,'Pivot Data'!$C$2:$C$301,D$12) -> 62305 | E13: =SUMIFS('Pivot Data'!$G$2:$G$301,'Pivot Data'!$D$2:$D$301,$A13,'Pivot Data'!$C$2:$C$301,E$12) -> 88287 | F13: =SUM(B13:E13) -> 377536
A14: Electronics | B14: =SUMIFS('Pivot Data'!$G$2:$G$301,'Pivot Data'!$D$2:$D$301,$A14,'Pivot Data'!$C$2:$C$301,B$12) -> 440479 | C14: =SUMIFS('Pivot Data'!$G$2:$G$301,'Pivot Data'!$D$2:$D$301,$A14,'Pivot Data'!$C$2:$C$301,C$12) -> 338910 | D14: =SUMIFS('Pivot Data'!$G$2:$G$301,'Pivot Data'!$D$2:$D$301,$A14,'Pivot Data'!$C$2:$C$301,D$12) -> 293911 | E14: =SUMIFS('Pivot Data'!$G$2:$G$301,'Pivot Data'!$D$2:$D$301,$A14,'Pivot Data'!$C$2:$C$301,E$12) -> 281995 | F14: =SUM(B14:E14) -> 1355295
A15: Furniture | B15: =SUMIFS('Pivot Data'!$G$2:$G$301,'Pivot Data'!$D$2:$D$301,$A15,'Pivot Data'!$C$2:$C$301,B$12) -> 353964 | C15: =SUMIFS('Pivot Data'!$G$2:$G$301,'Pivot Data'!$D$2:$D$301,$A15,'Pivot Data'!$C$2:$C$301,C$12) -> 363355 | D15: =SUMIFS('Pivot Data'!$G$2:$G$301,'Pivot Data'!$D$2:$D$301,$A15,'Pivot Data'!$C$2:$C$301,D$12) -> 476154 | E15: =SUMIFS('Pivot Data'!$G$2:$G$301,'Pivot Data'!$D$2:$D$301,$A15,'Pivot Data'!$C$2:$C$301,E$12) -> 113307 | F15: =SUM(B15:E15) -> 1306780
A16: Stationery | B16: =SUMIFS('Pivot Data'!$G$2:$G$301,'Pivot Data'!$D$2:$D$301,$A16,'Pivot Data'!$C$2:$C$301,B$12) -> 29002 | C16: =SUMIFS('Pivot Data'!$G$2:$G$301,'Pivot Data'!$D$2:$D$301,$A16,'Pivot Data'!$C$2:$C$301,C$12) -> 36616 | D16: =SUMIFS('Pivot Data'!$G$2:$G$301,'Pivot Data'!$D$2:$D$301,$A16,'Pivot Data'!$C$2:$C$301,D$12) -> 36613 | E16: =SUMIFS('Pivot Data'!$G$2:$G$301,'Pivot Data'!$D$2:$D$301,$A16,'Pivot Data'!$C$2:$C$301,E$12) -> 32928 | F16: =SUM(B16:E16) -> 135159
A17: Grand total | B17: =SUM(B13:B16) -> 973504 | C17: =SUM(C13:C16) -> 815766 | D17: =SUM(D13:D16) -> 868983 | E17: =SUM(E13:E16) -> 516517 | F17: =SUM(F13:F16) -> 3174770
A19: Revenue by month
A20: Month no. | B20: Month | C20: Revenue | D20: Orders
A21: 1 | B21: =TEXT(DATE(2025,A21,1),"mmmm") -> January | C21: =SUMPRODUCT((MONTH('Pivot Data'!$B$2:$B$301)=A21)*'Pivot Data'!$G$2:$G$301) -> 420579 | D21: =SUMPRODUCT(--(MONTH('Pivot Data'!$B$2:$B$301)=A21)) -> 33
A22: 2 | B22: =TEXT(DATE(2025,A22,1),"mmmm") -> February | C22: =SUMPRODUCT((MONTH('Pivot Data'!$B$2:$B$301)=A22)*'Pivot Data'!$G$2:$G$301) -> 231035 | D22: =SUMPRODUCT(--(MONTH('Pivot Data'!$B$2:$B$301)=A22)) -> 34
A23: 3 | B23: =TEXT(DATE(2025,A23,1),"mmmm") -> March | C23: =SUMPRODUCT((MONTH('Pivot Data'!$B$2:$B$301)=A23)*'Pivot Data'!$G$2:$G$301) -> 217972 | D23: =SUMPRODUCT(--(MONTH('Pivot Data'!$B$2:$B$301)=A23)) -> 19
A24: 4 | B24: =TEXT(DATE(2025,A24,1),"mmmm") -> April | C24: =SUMPRODUCT((MONTH('Pivot Data'!$B$2:$B$301)=A24)*'Pivot Data'!$G$2:$G$301) -> 246620 | D24: =SUMPRODUCT(--(MONTH('Pivot Data'!$B$2:$B$301)=A24)) -> 27
A25: 5 | B25: =TEXT(DATE(2025,A25,1),"mmmm") -> May | C25: =SUMPRODUCT((MONTH('Pivot Data'!$B$2:$B$301)=A25)*'Pivot Data'!$G$2:$G$301) -> 155695 | D25: =SUMPRODUCT(--(MONTH('Pivot Data'!$B$2:$B$301)=A25)) -> 21
A26: 6 | B26: =TEXT(DATE(2025,A26,1),"mmmm") -> June | C26: =SUMPRODUCT((MONTH('Pivot Data'!$B$2:$B$301)=A26)*'Pivot Data'!$G$2:$G$301) -> 227916 | D26: =SUMPRODUCT(--(MONTH('Pivot Data'!$B$2:$B$301)=A26)) -> 18
A27: 7 | B27: =TEXT(DATE(2025,A27,1),"mmmm") -> July | C27: =SUMPRODUCT((MONTH('Pivot Data'!$B$2:$B$301)=A27)*'Pivot Data'!$G$2:$G$301) -> 257182 | D27: =SUMPRODUCT(--(MONTH('Pivot Data'!$B$2:$B$301)=A27)) -> 24
A28: 8 | B28: =TEXT(DATE(2025,A28,1),"mmmm") -> August | C28: =SUMPRODUCT((MONTH('Pivot Data'!$B$2:$B$301)=A28)*'Pivot Data'!$G$2:$G$301) -> 317784 | D28: =SUMPRODUCT(--(MONTH('Pivot Data'!$B$2:$B$301)=A28)) -> 27
A29: 9 | B29: =TEXT(DATE(2025,A29,1),"mmmm") -> September | C29: =SUMPRODUCT((MONTH('Pivot Data'!$B$2:$B$301)=A29)*'Pivot Data'!$G$2:$G$301) -> 208938 | D29: =SUMPRODUCT(--(MONTH('Pivot Data'!$B$2:$B$301)=A29)) -> 23
A30: 10 | B30: =TEXT(DATE(2025,A30,1),"mmmm") -> October | C30: =SUMPRODUCT((MONTH('Pivot Data'!$B$2:$B$301)=A30)*'Pivot Data'!$G$2:$G$301) -> 278922 | D30: =SUMPRODUCT(--(MONTH('Pivot Data'!$B$2:$B$301)=A30)) -> 23
A31: 11 | B31: =TEXT(DATE(2025,A31,1),"mmmm") -> November | C31: =SUMPRODUCT((MONTH('Pivot Data'!$B$2:$B$301)=A31)*'Pivot Data'!$G$2:$G$301) -> 368091 | D31: =SUMPRODUCT(--(MONTH('Pivot Data'!$B$2:$B$301)=A31)) -> 30
A32: 12 | B32: =TEXT(DATE(2025,A32,1),"mmmm") -> December | C32: =SUMPRODUCT((MONTH('Pivot Data'!$B$2:$B$301)=A32)*'Pivot Data'!$G$2:$G$301) -> 244036 | D32: =SUMPRODUCT(--(MONTH('Pivot Data'!$B$2:$B$301)=A32)) -> 21
A33: Total | C33: =SUM(C21:C32) -> 3174770 | D33: =SUM(D21:D32) -> 300
A35: Revenue by salesperson | E35: Top 3 salespeople
A36: Salesperson | B36: Revenue | C36: Rank | E36: Rank | F36: Salesperson | G36: Revenue
A37: Anita | B37: =SUMIFS('Pivot Data'!$G$2:$G$301,'Pivot Data'!$E$2:$E$301,A37) -> 354327 | C37: =RANK(B37,$B$37:$B$44) -> 6 | E37: 1 | F37: =INDEX($A$37:$A$44,MATCH(E37,$C$37:$C$44,0)) -> Harsh | G37: =INDEX($B$37:$B$44,MATCH(E37,$C$37:$C$44,0)) -> 506447
A38: Bharat | B38: =SUMIFS('Pivot Data'!$G$2:$G$301,'Pivot Data'!$E$2:$E$301,A38) -> 443986 | C38: =RANK(B38,$B$37:$B$44) -> 4 | E38: 2 | F38: =INDEX($A$37:$A$44,MATCH(E38,$C$37:$C$44,0)) -> Divya | G38: =INDEX($B$37:$B$44,MATCH(E38,$C$37:$C$44,0)) -> 469132
A39: Chetan | B39: =SUMIFS('Pivot Data'!$G$2:$G$301,'Pivot Data'!$E$2:$E$301,A39) -> 259292 | C39: =RANK(B39,$B$37:$B$44) -> 8 | E39: 3 | F39: =INDEX($A$37:$A$44,MATCH(E39,$C$37:$C$44,0)) -> Farhan | G39: =INDEX($B$37:$B$44,MATCH(E39,$C$37:$C$44,0)) -> 465415
A40: Divya | B40: =SUMIFS('Pivot Data'!$G$2:$G$301,'Pivot Data'!$E$2:$E$301,A40) -> 469132 | C40: =RANK(B40,$B$37:$B$44) -> 2
A41: Farhan | B41: =SUMIFS('Pivot Data'!$G$2:$G$301,'Pivot Data'!$E$2:$E$301,A41) -> 465415 | C41: =RANK(B41,$B$37:$B$44) -> 3
A42: Gita | B42: =SUMIFS('Pivot Data'!$G$2:$G$301,'Pivot Data'!$E$2:$E$301,A42) -> 290308 | C42: =RANK(B42,$B$37:$B$44) -> 7
...

Sheet Pivot Data
A1: Order ID | B1: Date | C1: Region | D1: Category | E1: Salesperson | F1: Units | G1: Revenue | H1: Cost
A2: S1001 | B2: 45658 | C2: East | D2: Electronics | E2: Farhan | F2: 8 | G2: 20376 | H2: 15408
A3: S1002 | B3: 45658 | C3: East | D3: Electronics | E3: Isha | F3: 4 | G3: 14492 | H3: 8536
A4: S1003 | B4: 45660 | C4: East | D4: Furniture | E4: Divya | F4: 4 | G4: 20712 | H4: 13320
A5: S1004 | B5: 45662 | C5: South | D5: Stationery | E5: Gita | F5: 4 | G5: 2200 | H5: 1318
A6: S1005 | B6: 45663 | C6: North | D6: Electronics | E6: Bharat | F6: 3 | G6: 10599 | H6: 6684
A7: S1006 | B7: 45664 | C7: West | D7: Apparel | E7: Isha | F7: 5 | G7: 11415 | H7: 6722
A8: S1007 | B8: 45665 | C8: West | D8: Electronics | E8: Gita | F8: 4 | G8: 12780 | H8: 8153
A9: S1008 | B9: 45665 | C9: North | D9: Stationery | E9: Farhan | F9: 8 | G9: 2112 | H9: 1198
A10: S1009 | B10: 45665 | C10: East | D10: Apparel | E10: Farhan | F10: 1 | G10: 1989 | H10: 1418
A11: S1010 | B11: 45665 | C11: West | D11: Stationery | E11: Divya | F11: 1 | G11: 428 | H11: 249
A12: S1011 | B12: 45666 | C12: North | D12: Electronics | E12: Bharat | F12: 5 | G12: 12360 | H12: 9013
A13: S1012 | B13: 45666 | C13: South | D13: Furniture | E13: Isha | F13: 6 | G13: 18828 | H13: 13320
... A301: S1300 | B301: 46020 | C301: South | D301: Furniture | E301: Bharat | F301: 8 | G301: 33344 | H301: 23355

Sheet Lookups
A1: Lookups
A2: Product lookups, order pricing and commission slabs. Formulas in grey text are the XLOOKUP versions.
A4: Product ID | B4: Product Name | C4: Category | D4: Price (₹) | E4: Stock | G4: Order ID | H4: Product ID | I4: Qty | J4: Product Name | K4: Unit Price (₹) | L4: Line Total (₹) | N4: Sales at least (₹) | O4: Commission rate
A5: P001 | B5: Wireless Earbuds | C5: Electronics | D5: 2499 | E5: 40 | G5: ORD-501 | H5: P003 | I5: 2 | J5: =IFERROR(INDEX($B$5:$B$19,MATCH(H5,$A$5:$A$19,0)),"Not found") -> Power Bank | K5: =IFERROR(INDEX($D$5:$D$19,MATCH(H5,$A$5:$A$19,0)),0) -> 1499 | L5: =K5*I5 -> 2998 | N5: 0 | O5: 0
A6: P002 | B6: Smart Watch | C6: Electronics | D6: 5999 | E6: 15 | G6: ORD-502 | H6: P011 | I6: 1 | J6: =IFERROR(INDEX($B$5:$B$19,MATCH(H6,$A$5:$A$19,0)),"Not found") -> Face Serum | K6: =IFERROR(INDEX($D$5:$D$19,MATCH(H6,$A$5:$A$19,0)),0) -> 899 | L6: =K6*I6 -> 899 | N6: 10000 | O6: 0.02
A7: P003 | B7: Power Bank | C7: Electronics | D7: 1499 | E7: 60 | G7: ORD-503 | H7: P009 | I7: 1 | J7: =IFERROR(INDEX($B$5:$B$19,MATCH(H7,$A$5:$A$19,0)),"Not found") -> Coffee Maker | K7: =IFERROR(INDEX($D$5:$D$19,MATCH(H7,$A$5:$A$19,0)),0) -> 2999 | L7: =K7*I7 -> 2999 | N7: 25000 | O7: 0.04
A8: P004 | B8: Bluetooth Speaker | C8: Electronics | D8: 3299 | E8: 25 | G8: ORD-504 | H8: P099 | I8: 3 | J8: =IFERROR(INDEX($B$5:$B$19,MATCH(H8,$A$5:$A$19,0)),"Not found") -> Not found | K8: =IFERROR(INDEX($D$5:$D$19,MATCH(H8,$A$5:$A$19,0)),0) -> 0 | L8: =K8*I8 -> 0 | N8: 50000 | O8: 0.06
A9: P005 | B9: Cotton T-Shirt | C9: Apparel | D9: 799 | E9: 120 | G9: ORD-505 | H9: P005 | I9: 4 | J9: =IFERROR(INDEX($B$5:$B$19,MATCH(H9,$A$5:$A$19,0)),"Not found") -> Cotton T-Shirt | K9: =IFERROR(INDEX($D$5:$D$19,MATCH(H9,$A$5:$A$19,0)),0) -> 799 | L9: =K9*I9 -> 3196 | N9: 100000 | O9: 0.08
A10: P006 | B10: Denim Jeans | C10: Apparel | D10: 1999 | E10: 45 | G10: ORD-506 | H10: P002 | I10: 1 | J10: =IFERROR(INDEX($B$5:$B$19,MATCH(H10,$A$5:$A$19,0)),"Not found") -> Smart Watch | K10: =IFERROR(INDEX($D$5:$D$19,MATCH(H10,$A$5:$A$19,0)),0) -> 5999 | L10: =K10*I10 -> 5999
A11: P007 | B11: Hoodie | C11: Apparel | D11: 1799 | E11: 30 | G11: ORD-507 | H11: P014 | I11: 5 | J11: =IFERROR(INDEX($B$5:$B$19,MATCH(H11,$A$5:$A$19,0)),"Not found") -> Gel Pens Pack | K11: =IFERROR(INDEX($D$5:$D$19,MATCH(H11,$A$5:$A$19,0)),0) -> 199 | L11: =K11*I11 -> 995
A12: P008 | B12: Cotton Bedsheet | C12: Home | D12: 1299 | E12: 50 | G12: ORD-508 | H12: P007 | I12: 2 | J12: =IFERROR(INDEX($B$5:$B$19,MATCH(H12,$A$5:$A$19,0)),"Not found") -> Hoodie | K12: =IFERROR(INDEX($D$5:$D$19,MATCH(H12,$A$5:$A$19,0)),0) -> 1799 | L12: =K12*I12 -> 3598
A13: P009 | B13: Coffee Maker | C13: Home | D13: 2999 | E13: 12 | G13: ORD-509 | H13: P012 | I13: 1 | J13: =IFERROR(INDEX($B$5:$B$19,MATCH(H13,$A$5:$A$19,0)),"Not found") -> Perfume | K13: =IFERROR(INDEX($D$5:$D$19,MATCH(H13,$A$5:$A$19,0)),0) -> 1599 | L13: =K13*I13 -> 1599
A14: P010 | B14: Table Lamp | C14: Home | D14: 999 | E14: 35 | G14: ORD-510 | H14: P015 | I14: 3 | J14: =IFERROR(INDEX($B$5:$B$19,MATCH(H14,$A$5:$A$19,0)),"Not found") -> Desk Organizer | K14: =IFERROR(INDEX($D$5:$D$19,MATCH(H14,$A$5:$A$19,0)),0) -> 499 | L14: =K14*I14 -> 1497
A15: P011 | B15: Face Serum | C15: Beauty | D15: 899 | E15: 80
A16: P012 | B16: Perfume | C16: Beauty | D16: 1599 | E16: 22 | G16: Order table formulas (XLOOKUP version): Name =XLOOKUP(H5,$A$5:$A$19,$B$5:$B$19,"Not found") Price =XLOOKUP(H5,$A$5:$A$19,$D$5:$D$19,0) Total =K5*I5
A17: P013 | B17: Notebook | C17: Stationery | D17: 149 | E17: 300
A18: P014 | B18: Gel Pens Pack | C18: Stationery | D18: 199 | E18: 250
A19: P015 | B19: Desk Organizer | C19: Stationery | D19: 499 | E19: 70
A21: No. | B21: Question | E21: Answer | G21: XLOOKUP formula
A22: 1 | B22: Price of product P007 | E22: =INDEX(D5:D19,MATCH("P007",A5:A19,0)) -> 1799 | G22: =XLOOKUP("P007",A5:A19,D5:D19)
A23: 2 | B23: Category of the "Smart Watch" | E23: =INDEX(C5:C19,MATCH("Smart Watch",B5:B19,0)) -> Electronics | G23: =XLOOKUP("Smart Watch",B5:B19,C5:C19)
A24: 3 | B24: Product ID of "Coffee Maker" (lookup to the left) | E24: =INDEX(A5:A19,MATCH("Coffee Maker",B5:B19,0)) -> P009 | G24: =XLOOKUP("Coffee Maker",B5:B19,A5:A19)
A25: 4 | B25: Stock of P099, or "Not found" if missing | E25: =IFERROR(INDEX(E5:E19,MATCH("P099",A5:A19,0)),"Not found") -> Not found | G25: =XLOOKUP("P099",A5:A19,E5:E19,"Not found")
A26: 5 | B26: Commission rate on a ₹37,500 sale (approximate match) | E26: =INDEX(O5:O9,MATCH(37500,N5:N9,1)) -> 0.04 | G26: =XLOOKUP(37500,N5:N9,O5:O9,,-1)
A27: 6 | B27: Commission on a ₹1,20,000 sale | E27: =120000*INDEX(O5:O9,MATCH(120000,N5:N9,1)) -> 9600 | G27: =120000*XLOOKUP(120000,N5:N9,O5:O9,,-1)
A28: 7 | B28: Total value of the 10 orders | E28: =SUM(L5:L14) -> 23780 | G28: =SUM(L5:L14)

Sheet Text Functions
A1: Text functions
A2: Cleaning and splitting names, emails, phone numbers and order codes.
A4: Raw Name | B4: Email | C4: Phone | D4: Order Code | F4: Clean Name (trim, proper case) | G4: First Name | H4: Last Name | I4: Username (before @) | J4: Email Domain (after @) | K4: Phone last 4 digits | L4: Order Year (as a number) | M4: City Code (last 3 letters) | N4: "Last, First"
A5: ravi KUMAR | B5: ravi.kumar@gmail.com | C5: +91-98765-43210 | D5: ORD-2025-00123-MUM | F5: =PROPER(TRIM(A5)) -> Ravi Kumar | G5: =LEFT(F5,FIND(" ",F5)-1) -> Ravi | H5: =MID(F5,FIND(" ",F5)+1,50) -> Kumar | I5: =LEFT(B5,FIND("@",B5)-1) -> ravi.kumar | J5: =MID(B5,FIND("@",B5)+1,50) -> gmail.com | K5: =RIGHT(C5,4) -> 3210 | L5: =VALUE(MID(D5,5,4)) -> 2025 | M5: =RIGHT(D5,3) -> MUM | N5: =H5&", "&G5 -> Kumar, Ravi
A6: PRIYA sharma | B6: priya_s@outlook.com | C6: +91-91234-56789 | D6: ORD-2024-00456-DEL | F6: =PROPER(TRIM(A6)) -> Priya Sharma | G6: =LEFT(F6,FIND(" ",F6)-1) -> Priya | H6: =MID(F6,FIND(" ",F6)+1,50) -> Sharma | I6: =LEFT(B6,FIND("@",B6)-1) -> priya_s | J6: =MID(B6,FIND("@",B6)+1,50) -> outlook.com | K6: =RIGHT(C6,4) -> 6789 | L6: =VALUE(MID(D6,5,4)) -> 2024 | M6: =RIGHT(D6,3) -> DEL | N6: =H6&", "&G6 -> Sharma, Priya
A7: amit PATEL | B7: amit.patel@company.co.in | C7: +91-99887-76655 | D7: ORD-2025-00789-PUN | F7: =PROPER(TRIM(A7)) -> Amit Patel | G7: =LEFT(F7,FIND(" ",F7)-1) -> Amit | H7: =MID(F7,FIND(" ",F7)+1,50) -> Patel | I7: =LEFT(B7,FIND("@",B7)-1) -> amit.patel | J7: =MID(B7,FIND("@",B7)+1,50) -> company.co.in | K7: =RIGHT(C7,4) -> 6655 | L7: =VALUE(MID(D7,5,4)) -> 2025 | M7: =RIGHT(D7,3) -> PUN | N7: =H7&", "&G7 -> Patel, Amit
A8: sneha Iyer | B8: sneha.iyer@gmail.com | C8: +91-90000-11122 | D8: ORD-2023-00012-BLR | F8: =PROPER(TRIM(A8)) -> Sneha Iyer | G8: =LEFT(F8,FIND(" ",F8)-1) -> Sneha | H8: =MID(F8,FIND(" ",F8)+1,50) -> Iyer | I8: =LEFT(B8,FIND("@",B8)-1) -> sneha.iyer | J8: =MID(B8,FIND("@",B8)+1,50) -> gmail.com | K8: =RIGHT(C8,4) -> 1122 | L8: =VALUE(MID(D8,5,4)) -> 2023 | M8: =RIGHT(D8,3) -> BLR | N8: =H8&", "&G8 -> Iyer, Sneha
A9: ROHAN mehta | B9: rohan99@yahoo.com | C9: +91-95555-66677 | D9: ORD-2025-00345-MUM | F9: =PROPER(TRIM(A9)) -> Rohan Mehta | G9: =LEFT(F9,FIND(" ",F9)-1) -> Rohan | H9: =MID(F9,FIND(" ",F9)+1,50) -> Mehta | I9: =LEFT(B9,FIND("@",B9)-1) -> rohan99 | J9: =MID(B9,FIND("@",B9)+1,50) -> yahoo.com | K9: =RIGHT(C9,4) -> 6677 | L9: =VALUE(MID(D9,5,4)) -> 2025 | M9: =RIGHT(D9,3) -> MUM | N9: =H9&", "&G9 -> Mehta, Rohan
A10: kavita Nair | B10: kavita.nair@outlook.com | C10: +91-97777-88899 | D10: ORD-2024-00901-CHE | F10: =PROPER(TRIM(A10)) -> Kavita Nair | G10: =LEFT(F10,FIND(" ",F10)-1) -> Kavita | H10: =MID(F10,FIND(" ",F10)+1,50) -> Nair | I10: =LEFT(B10,FIND("@",B10)-1) -> kavita.nair | J10: =MID(B10,FIND("@",B10)+1,50) -> outlook.com | K10: =RIGHT(C10,4) -> 8899 | L10: =VALUE(MID(D10,5,4)) -> 2024 | M10: =RIGHT(D10,3) -> CHE | N10: =H10&", "&G10 -> Nair, Kavita
A11: arjun SINGH | B11: arjun.singh@company.co.in | C11: +91-93333-44455 | D11: ORD-2025-00567-DEL | F11: =PROPER(TRIM(A11)) -> Arjun Singh | G11: =LEFT(F11,FIND(" ",F11)-1) -> Arjun | H11: =MID(F11,FIND(" ",F11)+1,50) -> Singh | I11: =LEFT(B11,FIND("@",B11)-1) -> arjun.singh | J11: =MID(B11,FIND("@",B11)+1,50) -> company.co.in | K11: =RIGHT(C11,4) -> 4455 | L11: =VALUE(MID(D11,5,4)) -> 2025 | M11: =RIGHT(D11,3) -> DEL | N11: =H11&", "&G11 -> Singh, Arjun
A12: meera Joshi | B12: meera_j@gmail.com | C12: +91-92222-33344 | D12: ORD-2023-00234-PUN | F12: =PROPER(TRIM(A12)) -> Meera Joshi | G12: =LEFT(F12,FIND(" ",F12)-1) -> Meera | H12: =MID(F12,FIND(" ",F12)+1,50) -> Joshi | I12: =LEFT(B12,FIND("@",B12)-1) -> meera_j | J12: =MID(B12,FIND("@",B12)+1,50) -> gmail.com | K12: =RIGHT(C12,4) -> 3344 | L12: =VALUE(MID(D12,5,4)) -> 2023 | M12: =RIGHT(D12,3) -> PUN | N12: =H12&", "&G12 -> Joshi, Meera
A14: Formulas used (row 5)
F15: =PROPER(TRIM(A5)) | G15: =LEFT(F5,FIND(" ",F5)-1) | H15: =MID(F5,FIND(" ",F5)+1,50) | I15: =LEFT(B5,FIND("@",B5)-1) | J15: =MID(B5,FIND("@",B5)+1,50) | K15: =RIGHT(C5,4) | L15: =VALUE(MID(D5,5,4)) | M15: =RIGHT(D5,3) | N15: =H5&", "&G5

Sheet Date Functions
A1: Date functions
A2: Year, month, weekday, month-end, date differences and age. The as-of date is fixed so results stay the same.
A3: As of date | B3: 46295
A5: Order Date | B5: Ship Date | C5: Due Date | D5: Date of Birth | F5: Year of order | G5: Month number | H5: Day of month | I5: Month name | J5: Days from order to ship | K5: Weekday of order | L5: Last day of order month | M5: Days left to due date (negative = overdue) | N5: Age in complete years
A6: 46037 | B6: 46039 | C6: 46059 | D6: 34770 | F6: =YEAR(A6) -> 2026 | G6: =MONTH(A6) -> 1 | H6: =DAY(A6) -> 15 | I6: =TEXT(A6,"mmmm") -> January | J6: =B6-A6 -> 2 | K6: =TEXT(A6,"dddd") -> Thursday | L6: =EOMONTH(A6,0) -> 46053 | M6: =C6-$B$3 -> -236 | N6: =DATEDIF(D6,$B$3,"Y") -> 31
A7: 46056 | B7: 46061 | C7: 46106 | D7: 32452 | F7: =YEAR(A7) -> 2026 | G7: =MONTH(A7) -> 2 | H7: =DAY(A7) -> 3 | I7: =TEXT(A7,"mmmm") -> February | J7: =B7-A7 -> 5 | K7: =TEXT(A7,"dddd") -> Tuesday | L7: =EOMONTH(A7,0) -> 46081 | M7: =C7-$B$3 -> -189 | N7: =DATEDIF(D7,$B$3,"Y") -> 37
A8: 46109 | B8: 46112 | C8: 46122 | D8: 36737 | F8: =YEAR(A8) -> 2026 | G8: =MONTH(A8) -> 3 | H8: =DAY(A8) -> 28 | I8: =TEXT(A8,"mmmm") -> March | J8: =B8-A8 -> 3 | K8: =TEXT(A8,"dddd") -> Saturday | L8: =EOMONTH(A8,0) -> 46112 | M8: =C8-$B$3 -> -173 | N8: =DATEDIF(D8,$B$3,"Y") -> 26
A9: 46121 | B9: 46128 | C9: 46188 | D9: 33622 | F9: =YEAR(A9) -> 2026 | G9: =MONTH(A9) -> 4 | H9: =DAY(A9) -> 9 | I9: =TEXT(A9,"mmmm") -> April | J9: =B9-A9 -> 7 | K9: =TEXT(A9,"dddd") -> Thursday | L9: =EOMONTH(A9,0) -> 46142 | M9: =C9-$B$3 -> -107 | N9: =DATEDIF(D9,$B$3,"Y") -> 34
A10: 46163 | B10: 46165 | C10: 46195 | D10: 31320 | F10: =YEAR(A10) -> 2026 | G10: =MONTH(A10) -> 5 | H10: =DAY(A10) -> 21 | I10: =TEXT(A10,"mmmm") -> May | J10: =B10-A10 -> 2 | K10: =TEXT(A10,"dddd") -> Thursday | L10: =EOMONTH(A10,0) -> 46173 | M10: =C10-$B$3 -> -100 | N10: =DATEDIF(D10,$B$3,"Y") -> 41
A11: 46203 | B11: 46207 | C11: 46222 | D11: 36154 | F11: =YEAR(A11) -> 2026 | G11: =MONTH(A11) -> 6 | H11: =DAY(A11) -> 30 | I11: =TEXT(A11,"mmmm") -> June | J11: =B11-A11 -> 4 | K11: =TEXT(A11,"dddd") -> Tuesday | L11: =EOMONTH(A11,0) -> 46203 | M11: =C11-$B$3 -> -73 | N11: =DATEDIF(D11,$B$3,"Y") -> 27
A12: 46217 | B12: 46223 | C12: 46248 | D12: 36983 | F12: =YEAR(A12) -> 2026 | G12: =MONTH(A12) -> 7 | H12: =DAY(A12) -> 14 | I12: =TEXT(A12,"mmmm") -> July | J12: =B12-A12 -> 6 | K12: =TEXT(A12,"dddd") -> Tuesday | L12: =EOMONTH(A12,0) -> 46234 | M12: =C12-$B$3 -> -47 | N12: =DATEDIF(D12,$B$3,"Y") -> 25
A13: 46259 | B13: 46260 | C13: 46300 | D13: 33156 | F13: =YEAR(A13) -> 2026 | G13: =MONTH(A13) -> 8 | H13: =DAY(A13) -> 25 | I13: =TEXT(A13,"mmmm") -> August | J13: =B13-A13 -> 1 | K13: =TEXT(A13,"dddd") -> Tuesday | L13: =EOMONTH(A13,0) -> 46265 | M13: =C13-$B$3 -> 5 | N13: =DATEDIF(D13,$B$3,"Y") -> 35
A15: Formulas used (row 6)
F16: =YEAR(A6) | G16: =MONTH(A6) | H16: =DAY(A6) | I16: =TEXT(A6,"mmmm") | J16: =B6-A6 | K16: =TEXT(A6,"dddd") | L16: =EOMONTH(A6,0) | M16: =C6-$B$3 | N16: =DATEDIF(D6,$B$3,"Y")

Sheet Employee Analysis
A1: Employee analysis
A2: 20 questions on the Employee Data sheet, answered with formulas.
A4: No. | B4: Question | C4: Formula (Excel 2021 / 365 version) | D4: Answer | F4: Department | G4: Total salary
A5: 1 | B5: Total salary of all employees | C5: =SUM(E2:E41) | D5: =SUM('Employee Data'!$E$2:$E$41) -> 2657500 | F5: Sales | G5: =SUMIFS('Employee Data'!$E$2:$E$41,'Employee Data'!$C$2:$C$41,F5) -> 577500
A6: 2 | B6: Average salary of the Sales department (nearest whole number) | C6: =ROUND(AVERAGEIF(C2:C41,"Sales",E2:E41),0) | D6: =ROUND(AVERAGEIF('Employee Data'!$C$2:$C$41,"Sales",'Employee Data'!$E$2:$E$41),0) -> 64167 | F6: Finance | G6: =SUMIFS('Employee Data'!$E$2:$E$41,'Employee Data'!$C$2:$C$41,F6) -> 658000
A7: 3 | B7: Employees based in Pune | C7: =COUNTIF(F2:F41,"Pune") | D7: =COUNTIF('Employee Data'!$F$2:$F$41,"Pune") -> 10 | F7: HR | G7: =SUMIFS('Employee Data'!$E$2:$E$41,'Employee Data'!$C$2:$C$41,F7) -> 728500
A8: 4 | B8: Salary of employee E017 | C8: =XLOOKUP("E017",A2:A41,E2:E41) | D8: =INDEX('Employee Data'!$E$2:$E$41,MATCH("E017",'Employee Data'!$A$2:$A$41,0)) -> 43500 | F8: IT | G8: =SUMIFS('Employee Data'!$E$2:$E$41,'Employee Data'!$C$2:$C$41,F8) -> 439500
A9: 5 | B9: Highest-paid employee (trimmed, proper case) | C9: =PROPER(TRIM(XLOOKUP(MAX(E2:E41),E2:E41,B2:B41))) | D9: =PROPER(TRIM(INDEX('Employee Data'!$B$2:$B$41,MATCH(MAX('Employee Data'!$E$2:$E$41),'Employee Data'!$E$2:$E$41,0)))) -> Nikhil Patel | F9: Operations | G9: =SUMIFS('Employee Data'!$E$2:$E$41,'Employee Data'!$C$2:$C$41,F9) -> 254000
A10: 6 | B10: IT employees earning more than 60,000 | C10: =COUNTIFS(C2:C41,"IT",E2:E41,">60000") | D10: =COUNTIFS('Employee Data'!$C$2:$C$41,"IT",'Employee Data'!$E$2:$E$41,">60000") -> 4
A11: 7 | B11: Total salary of Delhi employees who joined on or after 1-Jan-2023 | C11: =SUMIFS(E2:E41,F2:F41,"Delhi",D2:D41,">="&DATE(2023,1,1)) | D11: =SUMIFS('Employee Data'!$E$2:$E$41,'Employee Data'!$F$2:$F$41,"Delhi",'Employee Data'!$D$2:$D$41,">="&DATE(2023,1,1)) -> 314000
A12: 8 | B12: Clean name of employee E005 | C12: =PROPER(TRIM(XLOOKUP("E005",A2:A41,B2:B41))) | D12: =PROPER(TRIM(INDEX('Employee Data'!$B$2:$B$41,MATCH("E005",'Employee Data'!$A$2:$A$41,0)))) -> Neha Joshi
A13: 9 | B13: First name of employee E010 | C13: =LEFT(x,FIND(" ",x)-1) where x = PROPER(TRIM(name)) | D13: =LEFT(PROPER(TRIM(INDEX('Employee Data'!$B$2:$B$41,MATCH("E010",'Employee Data'!$A$2:$A$41,0)))),FIND(" ",PROPER(TRIM(INDEX('Employee Data'!$B$2:$B$41,MATCH("E010",'Employee Data'!$A$2:$A$41,0)))))-1) -> Sneha
A14: 10 | B14: Email domain of employee E003 | C14: =MID(x,FIND("@",x)+1,50) where x = email | D14: =MID(INDEX('Employee Data'!$G$2:$G$41,MATCH("E003",'Employee Data'!$A$2:$A$41,0)),FIND("@",INDEX('Employee Data'!$G$2:$G$41,MATCH("E003",'Employee Data'!$A$2:$A$41,0)))+1,50) -> outlook.com
A15: 11 | B15: Year employee E020 joined | C15: =YEAR(XLOOKUP("E020",A2:A41,D2:D41)) | D15: =YEAR(INDEX('Employee Data'!$D$2:$D$41,MATCH("E020",'Employee Data'!$A$2:$A$41,0))) -> 2021
A16: 12 | B16: Complete years of service of E001 as of 30-Sep-2026 | C16: =DATEDIF(XLOOKUP("E001",A2:A41,D2:D41),DATE(2026,9,30),"Y") | D16: =DATEDIF(INDEX('Employee Data'!$D$2:$D$41,MATCH("E001",'Employee Data'!$A$2:$A$41,0)),DATE(2026,9,30),"Y") -> 5
A17: 13 | B17: Employees who joined in March (any year) | C17: =SUMPRODUCT(--(MONTH(D2:D41)=3)) | D17: =SUMPRODUCT(--(MONTH('Employee Data'!$D$2:$D$41)=3)) -> 4
A18: 14 | B18: Department with the highest total salary | C18: =INDEX(F5:F9,MATCH(MAX(G5:G9),G5:G9,0)) (helper table at F4:G9) | D18: =INDEX($F$5:$F$9,MATCH(MAX($G$5:$G$9),$G$5:$G$9,0)) -> HR
A19: 15 | B19: Bonus for E008: 10% if salary is 70,000 or more, otherwise 5% | C19: =IF(x>=70000,0.1,0.05)*x where x = salary | D19: =IF(INDEX('Employee Data'!$E$2:$E$41,MATCH("E008",'Employee Data'!$A$2:$A$41,0))>=70000,0.1,0.05)*INDEX('Employee Data'!$E$2:$E$41,MATCH("E008",'Employee Data'!$A$2:$A$41,0)) -> 3475
A20: 16 | B20: Number of unique cities | C20: =SUMPRODUCT(1/COUNTIF(F2:F41,F2:F41)) | D20: =SUMPRODUCT(1/COUNTIF('Employee Data'!$F$2:$F$41,'Employee Data'!$F$2:$F$41)) -> 4
A21: 17 | B21: Salary rank of employee E012 (1 = highest) | C21: =RANK(XLOOKUP("E012",A2:A41,E2:E41),E2:E41) | D21: =RANK(INDEX('Employee Data'!$E$2:$E$41,MATCH("E012",'Employee Data'!$A$2:$A$41,0)),'Employee Data'!$E$2:$E$41) -> 35
A22: 18 | B22: Median salary | C22: =MEDIAN(E2:E41) | D22: =MEDIAN('Employee Data'!$E$2:$E$41) -> 64750
A23: 19 | B23: Average salary of HR (same as a pivot of average salary by department) | C23: =ROUND(AVERAGEIF(C2:C41,"HR",E2:E41),0) | D23: =ROUND(AVERAGEIF('Employee Data'!$C$2:$C$41,"HR",'Employee Data'!$E$2:$E$41),0) -> 60708
A24: 20 | B24: Share of employees in Mumbai | C24: =COUNTIF(F2:F41,"Mumbai")/COUNTA(F2:F41) | D24: =COUNTIF('Employee Data'!$F$2:$F$41,"Mumbai")/COUNTA('Employee Data'!$F$2:$F$41) -> 0.375

Sheet Employee Data
A1: Emp ID | B1: Name | C1: Department | D1: Join Date | E1: Salary | F1: City | G1: Email
A2: E001 | B2: KARAN DESAI | C2: Finance | D2: 44196 | E2: 59000 | F2: Pune | G2: karan.desai@gmail.com
A3: E002 | B3: pooja joshi | C3: HR | D3: 44569 | E3: 81000 | F3: Bengaluru | G3: pooja.joshi@gmail.com
A4: E003 | B4: Priya Mehta | C4: Operations | D4: 43353 | E4: 46500 | F4: Bengaluru | G4: priya.mehta@outlook.com
A5: E004 | B5: Suresh Singh | C5: HR | D5: 45865 | E5: 38500 | F5: Mumbai | G5: suresh.singh@company.co.in
A6: E005 | B6: Neha Joshi | C6: IT | D6: 45230 | E6: 93000 | F6: Mumbai | G6: neha.joshi@company.co.in
A7: E006 | B7: Pooja Gupta | C7: Finance | D7: 43129 | E7: 71500 | F7: Pune | G7: pooja.gupta@outlook.com
A8: E007 | B8: Neha Mehta | C8: HR | D8: 45596 | E8: 33000 | F8: Delhi | G8: neha.mehta@company.co.in
A9: E008 | B9: SNEHA REDDY | C9: Finance | D9: 43318 | E9: 69500 | F9: Pune | G9: sneha.reddy@outlook.com
A10: E009 | B10: vikram SINGH | C10: Sales | D10: 44630 | E10: 77000 | F10: Pune | G10: vikram.singh@outlook.com
A11: E010 | B11: sneha sharma | C11: HR | D11: 44023 | E11: 58000 | F11: Mumbai | G11: sneha.sharma@company.co.in
A12: E011 | B12: ROHAN PATEL | C12: Sales | D12: 45731 | E12: 62000 | F12: Bengaluru | G12: rohan.patel@gmail.com
A13: E012 | B13: Karan Gupta | C13: HR | D13: 45362 | E13: 43500 | F13: Mumbai | G13: karan.gupta@outlook.com
... A41: E040 | B41: Rohan Joshi | C41: Sales | D41: 43423 | E41: 88000 | F41: Mumbai | G41: rohan.joshi@gmail.com
