Workbook

Sheet Plan
A1: Project 3 Kit: Retail Sales & Profit Dashboard
A2: Power Query merge, KPIs, ABC product analysis, RFM customer analysis, pivot tables and a one-page dashboard
A4: Block | B4: Time | C4: Sheet | D4: Goal
A5: 1. Power Query merge and clean | B5: 60 min | C5: 1 Clean Check, CSV files | D5: Combine 12 monthly CSV files, fix the four planted issues, reconcile counts to Sales Data
A6: 2. KPIs and formulas | B6: 40 min | C6: Sales Data, 2 KPI Tasks | D6: SUMIFS, COUNTIFS and SUMPRODUCT: sales, profit, margin, order value, returns, loss-making orders
A7: 3. Product ABC analysis | B7: 45 min | C7: Products, 3 ABC Tasks | D7: Find the few products that make most of the sales, the loss-makers and the dead stock
A8: 4. Customer RFM analysis | B8: 45 min | C8: Customers, 4 RFM Tasks | D8: Score every customer on recency, frequency and spend, then segment them
A9: 5. Pivot tables and dashboard | B9: 90 min | C9: 5 Dashboard Tasks | D9: Build the pivots yourself, then a one-page dashboard with slicers and a timeline
A10: 6. Insights and README | B10: 45 min | C10: 6 Insights | D10: Write five findings with numbers and recommendations, then package the repo
A11: 7. Review | B11: 20 min | C11: Answer Key | D11: Check your answers, log every mistake below, redo those tasks
A13: Data | B13: Practice data made up for this kit: 1,200 orders (one product per order), 40 products, 220 customers, Jan to Dec 2025, in ₹.
A14: Yellow cells | B14: Yellow means you type or fill down. Everything else is given. The Answer Key marks your yellow answers automatically.
A15: Your score | B15: ='Answer Key'!B3 -> 44 out of 44
A16: Versions | B16: Power Query, slicers and timelines need Excel 2016 or later (Microsoft 365 recommended). The Answer Key uses INDEX and MATCH, so it works in any version.
A18: Deliverables checklist
A19: Deliverable | B19: What it contains | C19: Where it goes | D19: Done? (Y/N)
A20: README.md | B20: Business problem, data, method, top 3 findings with numbers, dashboard screenshot | C20: Repo folder 03-retail-sales-profit-dashboard | D20: Y
A21: Excel workbook | B21: Power Query steps, KPI sheet, ABC, RFM, dashboard | C21: Same folder | D21: Y
A22: Dashboard screenshot | B22: One page: four KPI cards, three charts, two slicers, a timeline | C22: Top of the README | D22: Y
A23: One-page PDF summary | B23: Five findings and recommendations, like a client report | C23: Same folder, and a sample to send to clients | D23: Y
A24: 60-second screen recording | B24: Refresh, slicers and KPI cards in use | C24: Link in the README | D24: N
A26: Mistake log
A27: Question | B27: What went wrong | C27: Correct formula / idea | D27: Redone? (Y/N)
A28: Ex. KPI 3 | B28: Divided Profit by Cost instead of Sales | C28: =SUM(R2:R1201)/SUM(P2:P1201) | D28: Y

Sheet 1 Clean Check
A1: 1. Power Query: merge and clean
A2: Files: Retail_Sales_Monthly_CSVs.zip (Sales_2025-01.csv to Sales_2025-12.csv). Type your answers in the yellow cells.
A3: Your cleaned table should match the Sales Data sheet exactly. That sheet is the finished, clean version.
A4: No. | B4: Task | C4: Your answer | D4: Done? (Y/N)
A5: 1 | B5: Load the 12 CSV files with Data > Get Data > From File > From Folder and combine them. How many data rows are in the combined table before any cleaning? | C5: 1210 | D5: Y
A6: 2 | B6: Remove exact duplicate rows. How many rows did you remove? | C6: =C5-C7 -> 10 | D6: Y
A7: 3 | B7: How many rows are left after cleaning? | C7: =COUNTA('Sales Data'!$A$2:$A$1201) -> 1200 | D7: Y
A8: 4 | B8: What is the total of the Sales (₹) column after cleaning? | C8: =SUM('Sales Data'!$P$2:$P$1201) -> 5426671 | D8: Y
A9: 5 | B9: After trimming spaces and capitalising each word, how many different Customer Name values are there? | C9: =ROUND(SUMPRODUCT(1/COUNTIF('Sales Data'!$E$2:$E$1201,'Sales Data'!$E$2:$E$1201)),0) -> 220 | D9: Y
A10: 6 | B10: After fixing capitalisation, how many different Region values are there? | C10: =ROUND(SUMPRODUCT(1/COUNTIF('Sales Data'!$G$2:$G$1201,'Sales Data'!$G$2:$G$1201)),0) -> 4 | D10: Y
A11: 7 | B11: After standardising the Returned column to Y / N, how many rows have Returned = Y? | C11: =COUNTIF('Sales Data'!$S$2:$S$1201,"Y") -> 48 | D11: Y
A12: 8 | B12: Load the result as a connection plus a table named Sales_Clean, with the query named Sales_Clean. Mark Y when done. | C12: Do in Excel: paste Sales_Clean.m (see Power Query Steps sheet) | D12: N
A13: 9 | B13: Refresh test: change one Sales (₹) value in one CSV file, click Data > Refresh All, and confirm the total moved by the same amount. Mark Y when done. | C13: Do in Excel after loading the query | D13: N
A16: Planted issues (reference)
A17: No. | B17: Issue and where it appears | C17: Power Query step
A18: 1 | B18: Customer Name has extra spaces or all capitals on about 3% of rows, in every file. | C18: Transform > Format > Trim, then Capitalize Each Word
A19: 2 | B19: Region is written in lower case or all capitals on about 3% of rows, in every file. | C19: Transform > Format > Capitalize Each Word
A20: 3 | B20: Returned says Yes / No in the September to December files but Y / N in the others. | C20: Transform > Replace Values (Yes to Y, No to N)
A21: 4 | B21: Some rows appear twice inside a monthly file. | C21: Home > Remove Rows > Remove Duplicates (select all columns)

Sheet Power Query Steps
A1: Power Query steps for the Sales_Clean query
A2: Full M script: power_query/Sales_Clean.m in the repo. The same logic is reproduced and checked by scripts/clean_and_verify.py (1,210 raw rows -> 1,200 clean rows, ₹54,26,671 sales).
A4: Step | B4: Excel ribbon action | C4: Power Query step name | D4: Rows after step | E4: Why
A5: 1 | B5: Data > Get Data > From File > From Folder; Combine & Transform | C5: Source / Combined | D5: 1210 | E5: Stack the 12 monthly files into one table
A6: 2 | B6: Home > Use First Row as Headers | C6: Promoted Headers | D6: 1210 | E6: Each CSV has its own header row
A7: 3 | B7: Transform > Format > Trim, then Capitalize Each Word on Customer Name | C7: Cleaned Names | D7: 1210 | E7: Fixes extra spaces and ALL CAPS on ~3% of rows
A8: 4 | B8: Transform > Format > Trim, then Capitalize Each Word on Region | C8: Cleaned Region | D8: 1210 | E8: Fixes north / WEST style entries (11 distinct values -> 4)
A9: 5 | B9: Transform > Replace Values on Returned (Yes to Y, No to N) | C9: Standardised Returned | D9: 1210 | E9: Sep-Dec files use Yes / No
A10: 6 | B10: Transform > Data Type: dates, whole numbers, decimals | C10: Changed Type | D10: 1210 | E10: Correct types so SUM and date math work
A11: 7 | B11: Home > Remove Rows > Remove Duplicates (all columns selected) | C11: Removed Duplicates | D11: 1200 | E11: 10 exact duplicate rows planted inside monthly files
A12: 8 | B12: Close & Load To... > Connection + Table, query named Sales_Clean | C12: Sales_Clean | D12: 1200 | E12: Feeds the KPI, ABC, RFM and dashboard sheets
A15: Reconciliation (live formulas on Sales Data)
B16: Check | C16: Value
B17: Rows after cleaning | C17: =COUNTA('Sales Data'!$A$2:$A$1201) -> 1200
B18: Duplicate Order IDs left | C18: =COUNTA('Sales Data'!$A$2:$A$1201)-SUMPRODUCT(1/COUNTIF('Sales Data'!$A$2:$A$1201,'Sales Data'!$A$2:$A$1201)) -> 0
B19: Total Sales (₹) | C19: =SUM('Sales Data'!$P$2:$P$1201) -> 5426671
B20: Distinct Regions | C20: =ROUND(SUMPRODUCT(1/COUNTIF('Sales Data'!$G$2:$G$1201,'Sales Data'!$G$2:$G$1201)),0) -> 4
B21: Returned = Y | C21: =COUNTIF('Sales Data'!$S$2:$S$1201,"Y") -> 48

Sheet Sales Data
A1: Order ID | B1: Order Date | C1: Ship Date | D1: Customer ID | E1: Customer Name | F1: Segment | G1: Region | H1: City | I1: Category | J1: Sub-Category | K1: Product ID | L1: Product Name | M1: Qty | N1: Unit Price (₹) | O1: Discount | P1: Sales (₹) | Q1: Cost (₹) | R1: Profit (₹) | S1: Returned | T1: Discount Band
A2: ORD-2001 | B2: 45658 | C2: 45659 | D2: C218 | E2: Rajat Mehta | F2: Consumer | G2: West | H2: Pune | I2: Apparel | J2: Bottomwear | K2: P006 | L2: Denim Jeans | M2: 2 | N2: 1999 | O2: 0.3 | P2: 2799 | Q2: 2100 | R2: 699 | S2: N | T2: =IF(O2=0,"No discount",IF(O2<=0.2,"Up to 20%","Above 20%")) -> Above 20%
A3: ORD-2002 | B3: 45658 | C3: 45659 | D3: C024 | E3: Rajat Bhatt | F3: Consumer | G3: South | H3: Chennai | I3: Home | J3: Decor | K3: P025 | L3: Cushion Cover Set | M3: 1 | N3: 699 | O3: 0.05 | P3: 664 | Q3: 320 | R3: 344 | S3: N | T3: =IF(O3=0,"No discount",IF(O3<=0.2,"Up to 20%","Above 20%")) -> Up to 20%
A4: ORD-2003 | B4: 45658 | C4: 45660 | D4: C172 | E4: Pankaj Kapoor | F4: Home Office | G4: South | H4: Bengaluru | I4: Home | J4: Decor | K4: P010 | L4: Table Lamp | M4: 1 | N4: 999 | O4: 0.05 | P4: 949 | Q4: 520 | R4: 429 | S4: N | T4: =IF(O4=0,"No discount",IF(O4<=0.2,"Up to 20%","Above 20%")) -> Up to 20%
A5: ORD-2004 | B5: 45660 | C5: 45662 | D5: C148 | E5: Divya Jain | F5: Home Office | G5: West | H5: Pune | I5: Apparel | J5: Footwear | K5: P020 | L5: Running Shoes | M5: 1 | N5: 3299 | O5: 0.4 | P5: 1979 | Q5: 1900 | R5: 79 | S5: N | T5: =IF(O5=0,"No discount",IF(O5<=0.2,"Up to 20%","Above 20%")) -> Above 20%
A6: ORD-2005 | B6: 45660 | C6: 45664 | D6: C065 | E6: Aditya Shah | F6: Consumer | G6: South | H6: Hyderabad | I6: Furniture | J6: Seating | K6: P033 | L6: Office Chair | M6: 1 | N6: 8999 | O6: 0.3 | P6: 6299 | Q6: 6800 | R6: -501 | S6: N | T6: =IF(O6=0,"No discount",IF(O6<=0.2,"Up to 20%","Above 20%")) -> Above 20%
A7: ORD-2006 | B7: 45660 | C7: 45666 | D7: C212 | E7: Karan Das | F7: Home Office | G7: South | H7: Hyderabad | I7: Beauty | J7: Makeup | K7: P027 | L7: Lip Balm Set | M7: 4 | N7: 399 | O7: 0 | P7: 1596 | Q7: 640 | R7: 956 | S7: N | T7: =IF(O7=0,"No discount",IF(O7<=0.2,"Up to 20%","Above 20%")) -> No discount
A8: ORD-2007 | B8: 45661 | C8: 45664 | D8: C200 | E8: Aditya Joshi | F8: Consumer | G8: North | H8: Delhi | I8: Electronics | J8: Accessories | K8: P017 | L8: Mechanical Keyboard | M8: 1 | N8: 3499 | O8: 0.05 | P8: 3324 | Q8: 2200 | R8: 1124 | S8: N | T8: =IF(O8=0,"No discount",IF(O8<=0.2,"Up to 20%","Above 20%")) -> Up to 20%
A9: ORD-2008 | B9: 45662 | C9: 45668 | D9: C200 | E9: Aditya Joshi | F9: Consumer | G9: North | H9: Delhi | I9: Furniture | J9: Storage | K9: P035 | L9: Bookshelf | M9: 1 | N9: 5999 | O9: 0.3 | P9: 4199 | Q9: 4600 | R9: -401 | S9: N | T9: =IF(O9=0,"No discount",IF(O9<=0.2,"Up to 20%","Above 20%")) -> Above 20%
A10: ORD-2009 | B10: 45662 | C10: 45665 | D10: C034 | E10: Ramesh Saxena | F10: Corporate | G10: North | H10: Delhi | I10: Electronics | J10: Accessories | K10: P017 | L10: Mechanical Keyboard | M10: 1 | N10: 3499 | O10: 0.05 | P10: 3324 | Q10: 2200 | R10: 1124 | S10: N | T10: =IF(O10=0,"No discount",IF(O10<=0.2,"Up to 20%","Above 20%")) -> Up to 20%
A11: ORD-2010 | B11: 45663 | C11: 45665 | D11: C163 | E11: Kavya Das | F11: Corporate | G11: West | H11: Pune | I11: Beauty | J11: Skincare | K11: P011 | L11: Face Serum | M11: 3 | N11: 899 | O11: 0.15 | P11: 2292 | Q11: 1140 | R11: 1152 | S11: N | T11: =IF(O11=0,"No discount",IF(O11<=0.2,"Up to 20%","Above 20%")) -> Up to 20%
A12: ORD-2011 | B12: 45663 | C12: 45667 | D12: C137 | E12: Priya Verma | F12: Consumer | G12: South | H12: Bengaluru | I12: Furniture | J12: Storage | K12: P035 | L12: Bookshelf | M12: 1 | N12: 5999 | O12: 0.1 | P12: 5399 | Q12: 4600 | R12: 799 | S12: N | T12: =IF(O12=0,"No discount",IF(O12<=0.2,"Up to 20%","Above 20%")) -> Up to 20%
A13: ORD-2012 | B13: 45664 | C13: 45667 | D13: C135 | E13: Sneha Bhatt | F13: Corporate | G13: South | H13: Hyderabad | I13: Electronics | J13: Audio | K13: P018 | L13: Noise-Cancelling Headphones | M13: 1 | N13: 7999 | O13: 0.05 | P13: 7599 | Q13: 5600 | R13: 1999 | S13: N | T13: =IF(O13=0,"No discount",IF(O13<=0.2,"Up to 20%","Above 20%")) -> Up to 20%
... A1201: ORD-3200 | B1201: 46022 | C1201: 46023 | D1201: C188 | E1201: Zoya Desai | F1201: Home Office | G1201: North | H1201: Delhi | I1201: Apparel | J1201: Bottomwear | K1201: P006 | L1201: Denim Jeans | M1201: 1 | N1201: 1999 | O1201: 0.3 | P1201: 1399 | Q1201: 1050 | R1201: 349 | S1201: N | T1201: =IF(O1201=0,"No discount",IF(O1201<=0.2,"Up to 20%","Above 20%")) -> Above 20%

Sheet 2 KPI Tasks
A1: 2. KPIs and formulas
A2: Use the Sales Data sheet and formulas such as SUMIFS, COUNTIFS and SUMPRODUCT. Type your answers in the yellow cells.
A4: No. | B4: Task | C4: Your answer | D4: Done? (Y/N)
A5: 1 | B5: What is the total Sales (₹)? | C5: =SUM('Sales Data'!$P$2:$P$1201) -> 5426671 | D5: Y
A6: 2 | B6: What is the total Profit (₹)? | C6: =SUM('Sales Data'!$R$2:$R$1201) -> 1212441 | D6: Y
A7: 3 | B7: What is the overall profit margin (Profit divided by Sales)? Enter it as a percentage. | C7: =C6/C5 -> 0.22342261 | D7: Y
A8: 4 | B8: How many orders are there? (Each row is one order.) | C8: =COUNTA('Sales Data'!$A$2:$A$1201) -> 1200 | D8: Y
A9: 5 | B9: What is the average order value (₹), Sales divided by the number of orders? | C9: =C5/C8 -> 4522.2258 | D9: Y
A10: 6 | B10: What is the return rate, orders with Returned = Y divided by all orders? Enter it as a percentage. | C10: =COUNTIF('Sales Data'!$S$2:$S$1201,"Y")/C8 -> 0.04 | D10: Y
A11: 7 | B11: Which month has the highest Sales? Enter the month name. | C11: =INDEX(Pivots!$B$24:$B$35,MATCH(MAX(Pivots!$D$24:$D$35),Pivots!$D$24:$D$35,0)) -> November | D11: Y
A12: 8 | B12: By what percentage did Sales change from November to December? (December minus November, divided by November.) | C12: =(Pivots!$D$35-Pivots!$D$34)/Pivots!$D$34 -> -0.31373624 | D12: Y
A13: 9 | B13: What are the total Sales (₹) of the West region on orders with a discount of 20% or more? | C13: =SUMIFS('Sales Data'!$P$2:$P$1201,'Sales Data'!$G$2:$G$1201,"West",'Sales Data'!$O$2:$O$1201,">=0.2") -> 698690 | D13: Y
A14: 10 | B14: How many orders lost money (Profit below zero)? | C14: =COUNTIF('Sales Data'!$R$2:$R$1201,"<0") -> 92 | D14: Y
A15: 11 | B15: What is the total loss (₹) on those orders? Enter it as a positive number. | C15: =-SUMIF('Sales Data'!$R$2:$R$1201,"<0") -> 85926 | D15: Y
A16: 12 | B16: What is the average number of days from order to ship? (2 decimal places) | C16: =ROUND(SUMPRODUCT('Sales Data'!$C$2:$C$1201-'Sales Data'!$B$2:$B$1201)/COUNTA('Sales Data'!$A$2:$A$1201),2) -> 4 | D16: Y

Sheet Products
A1: Products: ABC analysis
A2: Fill down each yellow column from the first row. Read the Sales Data sheet; do not type numbers in.
A4: Product ID | B4: Product Name | C4: Category | D4: Sub-Category | E4: Unit Price (₹) | F4: Unit Cost (₹) | H4: Units Sold | I4: Sales (₹) | J4: Profit (₹) | K4: Profit Margin | L4: Sales Share | M4: Cumulative Share | N4: ABC Class
A5: P001 | B5: Wireless Earbuds | C5: Electronics | D5: Audio | E5: 2499 | F5: 1500 | H5: =SUMIFS('Sales Data'!$M$2:$M$1201,'Sales Data'!$K$2:$K$1201,A5) -> 10 | I5: =SUMIFS('Sales Data'!$P$2:$P$1201,'Sales Data'!$K$2:$K$1201,A5) -> 24240 | J5: =SUMIFS('Sales Data'!$R$2:$R$1201,'Sales Data'!$K$2:$K$1201,A5) -> 9240 | K5: =IF(I5=0,0,J5/I5) -> 0.38118812 | L5: =I5/SUM($I$5:$I$44) -> 0.0044668269 | M5: =SUMIF($I$5:$I$44,">="&I5)/SUM($I$5:$I$44) -> 0.97916421 | N5: =IF(M5<=0.8,"A",IF(M5<=0.95,"B",IF(M5<=1,"C","C"))) -> C
A6: P002 | B6: Smart Watch | C6: Electronics | D6: Wearables | E6: 5999 | F6: 4300 | H6: =SUMIFS('Sales Data'!$M$2:$M$1201,'Sales Data'!$K$2:$K$1201,A6) -> 37 | I6: =SUMIFS('Sales Data'!$P$2:$P$1201,'Sales Data'!$K$2:$K$1201,A6) -> 208164 | J6: =SUMIFS('Sales Data'!$R$2:$R$1201,'Sales Data'!$K$2:$K$1201,A6) -> 49064 | K6: =IF(I6=0,0,J6/I6) -> 0.23569878 | L6: =I6/SUM($I$5:$I$44) -> 0.038359429 | M6: =SUMIF($I$5:$I$44,">="&I6)/SUM($I$5:$I$44) -> 0.66130506 | N6: =IF(M6<=0.8,"A",IF(M6<=0.95,"B",IF(M6<=1,"C","C"))) -> A
A7: P003 | B7: Power Bank | C7: Electronics | D7: Accessories | E7: 1499 | F7: 900 | H7: =SUMIFS('Sales Data'!$M$2:$M$1201,'Sales Data'!$K$2:$K$1201,A7) -> 23 | I7: =SUMIFS('Sales Data'!$P$2:$P$1201,'Sales Data'!$K$2:$K$1201,A7) -> 31852 | J7: =SUMIFS('Sales Data'!$R$2:$R$1201,'Sales Data'!$K$2:$K$1201,A7) -> 11152 | K7: =IF(I7=0,0,J7/I7) -> 0.3501193 | L7: =I7/SUM($I$5:$I$44) -> 0.0058695285 | M7: =SUMIF($I$5:$I$44,">="&I7)/SUM($I$5:$I$44) -> 0.96475906 | N7: =IF(M7<=0.8,"A",IF(M7<=0.95,"B",IF(M7<=1,"C","C"))) -> C
A8: P004 | B8: Bluetooth Speaker | C8: Electronics | D8: Audio | E8: 3299 | F8: 2100 | H8: =SUMIFS('Sales Data'!$M$2:$M$1201,'Sales Data'!$K$2:$K$1201,A8) -> 20 | I8: =SUMIFS('Sales Data'!$P$2:$P$1201,'Sales Data'!$K$2:$K$1201,A8) -> 63670 | J8: =SUMIFS('Sales Data'!$R$2:$R$1201,'Sales Data'!$K$2:$K$1201,A8) -> 21670 | K8: =IF(I8=0,0,J8/I8) -> 0.34034867 | L8: =I8/SUM($I$5:$I$44) -> 0.011732792 | M8: =SUMIF($I$5:$I$44,">="&I8)/SUM($I$5:$I$44) -> 0.90846635 | N8: =IF(M8<=0.8,"A",IF(M8<=0.95,"B",IF(M8<=1,"C","C"))) -> B
A9: P005 | B9: Cotton T-Shirt | C9: Apparel | D9: Topwear | E9: 799 | F9: 380 | H9: =SUMIFS('Sales Data'!$M$2:$M$1201,'Sales Data'!$K$2:$K$1201,A9) -> 13 | I9: =SUMIFS('Sales Data'!$P$2:$P$1201,'Sales Data'!$K$2:$K$1201,A9) -> 7830 | J9: =SUMIFS('Sales Data'!$R$2:$R$1201,'Sales Data'!$K$2:$K$1201,A9) -> 2890 | K9: =IF(I9=0,0,J9/I9) -> 0.36909323 | L9: =I9/SUM($I$5:$I$44) -> 0.0014428735 | M9: =SUMIF($I$5:$I$44,">="&I9)/SUM($I$5:$I$44) -> 0.99968544 | N9: =IF(M9<=0.8,"A",IF(M9<=0.95,"B",IF(M9<=1,"C","C"))) -> C
A10: P006 | B10: Denim Jeans | C10: Apparel | D10: Bottomwear | E10: 1999 | F10: 1050 | H10: =SUMIFS('Sales Data'!$M$2:$M$1201,'Sales Data'!$K$2:$K$1201,A10) -> 85 | I10: =SUMIFS('Sales Data'!$P$2:$P$1201,'Sales Data'!$K$2:$K$1201,A10) -> 131131 | J10: =SUMIFS('Sales Data'!$R$2:$R$1201,'Sales Data'!$K$2:$K$1201,A10) -> 41881 | K10: =IF(I10=0,0,J10/I10) -> 0.31938291 | L10: =I10/SUM($I$5:$I$44) -> 0.02416417 | M10: =SUMIF($I$5:$I$44,">="&I10)/SUM($I$5:$I$44) -> 0.7924713 | N10: =IF(M10<=0.8,"A",IF(M10<=0.95,"B",IF(M10<=1,"C","C"))) -> A
A11: P007 | B11: Hoodie | C11: Apparel | D11: Topwear | E11: 1799 | F11: 950 | H11: =SUMIFS('Sales Data'!$M$2:$M$1201,'Sales Data'!$K$2:$K$1201,A11) -> 36 | I11: =SUMIFS('Sales Data'!$P$2:$P$1201,'Sales Data'!$K$2:$K$1201,A11) -> 53429 | J11: =SUMIFS('Sales Data'!$R$2:$R$1201,'Sales Data'!$K$2:$K$1201,A11) -> 19229 | K11: =IF(I11=0,0,J11/I11) -> 0.35989818 | L11: =I11/SUM($I$5:$I$44) -> 0.009845631 | M11: =SUMIF($I$5:$I$44,">="&I11)/SUM($I$5:$I$44) -> 0.92878765 | N11: =IF(M11<=0.8,"A",IF(M11<=0.95,"B",IF(M11<=1,"C","C"))) -> B
A12: P008 | B12: Cotton Bedsheet | C12: Home | D12: Bedding | E12: 1299 | F12: 700 | H12: =SUMIFS('Sales Data'!$M$2:$M$1201,'Sales Data'!$K$2:$K$1201,A12) -> 64 | I12: =SUMIFS('Sales Data'!$P$2:$P$1201,'Sales Data'!$K$2:$K$1201,A12) -> 75598 | J12: =SUMIFS('Sales Data'!$R$2:$R$1201,'Sales Data'!$K$2:$K$1201,A12) -> 30798 | K12: =IF(I12=0,0,J12/I12) -> 0.40739173 | L12: =I12/SUM($I$5:$I$44) -> 0.013930824 | M12: =SUMIF($I$5:$I$44,">="&I12)/SUM($I$5:$I$44) -> 0.89673356 | N12: =IF(M12<=0.8,"A",IF(M12<=0.95,"B",IF(M12<=1,"C","C"))) -> B
A13: P009 | B13: Coffee Maker | C13: Home | D13: Kitchen | E13: 2999 | F13: 2000 | H13: =SUMIFS('Sales Data'!$M$2:$M$1201,'Sales Data'!$K$2:$K$1201,A13) -> 105 | I13: =SUMIFS('Sales Data'!$P$2:$P$1201,'Sales Data'!$K$2:$K$1201,A13) -> 287750 | J13: =SUMIFS('Sales Data'!$R$2:$R$1201,'Sales Data'!$K$2:$K$1201,A13) -> 77750 | K13: =IF(I13=0,0,J13/I13) -> 0.27019983 | L13: =I13/SUM($I$5:$I$44) -> 0.053025142 | M13: =SUMIF($I$5:$I$44,">="&I13)/SUM($I$5:$I$44) -> 0.57233007 | N13: =IF(M13<=0.8,"A",IF(M13<=0.95,"B",IF(M13<=1,"C","C"))) -> A
A14: P010 | B14: Table Lamp | C14: Home | D14: Decor | E14: 999 | F14: 520 | H14: =SUMIFS('Sales Data'!$M$2:$M$1201,'Sales Data'!$K$2:$K$1201,A14) -> 81 | I14: =SUMIFS('Sales Data'!$P$2:$P$1201,'Sales Data'!$K$2:$K$1201,A14) -> 75622 | J14: =SUMIFS('Sales Data'!$R$2:$R$1201,'Sales Data'!$K$2:$K$1201,A14) -> 33502 | K14: =IF(I14=0,0,J14/I14) -> 0.44301923 | L14: =I14/SUM($I$5:$I$44) -> 0.013935247 | M14: =SUMIF($I$5:$I$44,">="&I14)/SUM($I$5:$I$44) -> 0.88280273 | N14: =IF(M14<=0.8,"A",IF(M14<=0.95,"B",IF(M14<=1,"C","C"))) -> B
A15: P011 | B15: Face Serum | C15: Beauty | D15: Skincare | E15: 899 | F15: 380 | H15: =SUMIFS('Sales Data'!$M$2:$M$1201,'Sales Data'!$K$2:$K$1201,A15) -> 63 | I15: =SUMIFS('Sales Data'!$P$2:$P$1201,'Sales Data'!$K$2:$K$1201,A15) -> 49487 | J15: =SUMIFS('Sales Data'!$R$2:$R$1201,'Sales Data'!$K$2:$K$1201,A15) -> 25547 | K15: =IF(I15=0,0,J15/I15) -> 0.51623659 | L15: =I15/SUM($I$5:$I$44) -> 0.0091192188 | M15: =SUMIF($I$5:$I$44,">="&I15)/SUM($I$5:$I$44) -> 0.93790687 | N15: =IF(M15<=0.8,"A",IF(M15<=0.95,"B",IF(M15<=1,"C","C"))) -> B
A16: P012 | B16: Perfume | C16: Beauty | D16: Fragrance | E16: 1599 | F16: 750 | H16: =SUMIFS('Sales Data'!$M$2:$M$1201,'Sales Data'!$K$2:$K$1201,A16) -> 92 | I16: =SUMIFS('Sales Data'!$P$2:$P$1201,'Sales Data'!$K$2:$K$1201,A16) -> 129437 | J16: =SUMIFS('Sales Data'!$R$2:$R$1201,'Sales Data'!$K$2:$K$1201,A16) -> 60437 | K16: =IF(I16=0,0,J16/I16) -> 0.46692213 | L16: =I16/SUM($I$5:$I$44) -> 0.023852008 | M16: =SUMIF($I$5:$I$44,">="&I16)/SUM($I$5:$I$44) -> 0.8163233 | N16: =IF(M16<=0.8,"A",IF(M16<=0.95,"B",IF(M16<=1,"C","C"))) -> B
... A44: P040 | B44: Ceramic Mug Set | C44: Home | D44: Kitchen | E44: 599 | F44: 300 | H44: =SUMIFS('Sales Data'!$M$2:$M$1201,'Sales Data'!$K$2:$K$1201,A44) -> 3 | I44: =SUMIFS('Sales Data'!$P$2:$P$1201,'Sales Data'!$K$2:$K$1201,A44) -> 1707 | J44: =SUMIFS('Sales Data'!$R$2:$R$1201,'Sales Data'!$K$2:$K$1201,A44) -> 807 | K44: =IF(I44=0,0,J44/I44) -> 0.47275923 | L44: =I44/SUM($I$5:$I$44) -> 0.00031455749 | M44: =SUMIF($I$5:$I$44,">="&I44)/SUM($I$5:$I$44) -> 1 | N44: =IF(M44<=0.8,"A",IF(M44<=0.95,"B",IF(M44<=1,"C","C"))) -> C
A46: Note: K = J/I; L = I / total sales; M = share of sales from this product and every product that sold at least as much (ranked cumulative share, ties handled); N: A <= 80%, B <= 95%, C = rest. P031 and P039 had no sales.

Sheet 3 ABC Tasks
A1: 3. Product ABC analysis
A2: Work on the Products sheet, then type your answers in the yellow cells.
A4: No. | B4: Task | C4: Your answer | D4: Done? (Y/N)
A5: 1 | B5: Fill Units Sold, Sales and Profit for all 40 products on the Products sheet. Enter the sum of the Sales (₹) column. | C5: =SUM(Products!$I$5:$I$44) -> 5426671 | D5: Y
A6: 2 | B6: Which product has the highest Sales? Enter the product name. | C6: =INDEX(Products!$B$5:$B$44,MATCH(MAX(Products!$I$5:$I$44),Products!$I$5:$I$44,0)) -> Noise-Cancelling Headphones | D6: Y
A7: 3 | B7: Which product has the highest Profit? Enter the product name. | C7: =INDEX(Products!$B$5:$B$44,MATCH(MAX(Products!$J$5:$J$44),Products!$J$5:$J$44,0)) -> Noise-Cancelling Headphones | D7: Y
A8: 4 | B8: How many products have a negative total Profit? | C8: =COUNTIF(Products!$J$5:$J$44,"<0") -> 1 | D8: Y
A9: 5 | B9: Fill Profit Margin, Sales Share, Cumulative Share and ABC Class (A = cumulative share up to 80%, B = up to 95%, C = the rest). How many products are Class A? | C9: =COUNTIF(Products!$N$5:$N$44,"A") -> 13 | D9: Y
A10: 6 | B10: What share of total Sales do the Class A products make? Enter it as a percentage. | C10: =SUMIF(Products!$N$5:$N$44,"A",Products!$I$5:$I$44)/SUM(Products!$I$5:$I$44) -> 0.7924713 | D10: Y
A11: 7 | B11: How many products sold fewer than 10 units in the year? (dead-stock candidates) | C11: =COUNTIF(Products!$H$5:$H$44,"<10") -> 4 | D11: Y
A12: 8 | B12: Which Category has the highest profit margin? Enter the category name. | C12: =INDEX(Pivots!$A$64:$A$69,MATCH(MAX(Pivots!$E$64:$E$69),Pivots!$E$64:$E$69,0)) -> Beauty | D12: Y
A13: 9 | B13: What is the total Profit (₹) of the Furniture category? | C13: =SUMIFS('Sales Data'!$R$2:$R$1201,'Sales Data'!$I$2:$I$1201,"Furniture") -> 56785 | D13: Y

Sheet Customers
A1: Customers: RFM analysis
A2: Fill down each yellow column from the first row. Use the lookup tables on the right (columns P and Q) with approximate match.
A4: Customer ID | B4: Customer Name | C4: Segment | D4: City | F4: Orders | G4: Last Order Date | H4: Days Since Last Order | I4: Total Sales (₹) | J4: R Score | K4: F Score | L4: M Score | M4: Total Score | N4: RFM Segment | P4: As of date | Q4: 46022 | R4: Fixed so answers do not change (last day of the data)
A5: C001 | B5: Neha Verma | C5: Consumer | D5: Bengaluru | F5: =COUNTIF('Sales Data'!$D$2:$D$1201,A5) -> 4 | G5: =_xlfn.MAXIFS('Sales Data'!$B$2:$B$1201,'Sales Data'!$D$2:$D$1201,A5) -> 45965 | H5: =$Q$4-G5 -> 57 | I5: =SUMIFS('Sales Data'!$P$2:$P$1201,'Sales Data'!$D$2:$D$1201,A5) -> 8654 | J5: =INDEX($Q$7:$Q$9,MATCH(H5,$P$7:$P$9,1)) -> 2 | K5: =INDEX($Q$12:$Q$14,MATCH(F5,$P$12:$P$14,1)) -> 2 | L5: =INDEX($Q$17:$Q$19,MATCH(I5,$P$17:$P$19,1)) -> 1 | M5: =J5+K5+L5 -> 5 | N5: =INDEX($Q$22:$Q$25,MATCH(M5,$P$22:$P$25,1)) -> At Risk
A6: C002 | B6: Ramesh Shah | C6: Consumer | D6: Delhi | F6: =COUNTIF('Sales Data'!$D$2:$D$1201,A6) -> 3 | G6: =_xlfn.MAXIFS('Sales Data'!$B$2:$B$1201,'Sales Data'!$D$2:$D$1201,A6) -> 45882 | H6: =$Q$4-G6 -> 140 | I6: =SUMIFS('Sales Data'!$P$2:$P$1201,'Sales Data'!$D$2:$D$1201,A6) -> 23645 | J6: =INDEX($Q$7:$Q$9,MATCH(H6,$P$7:$P$9,1)) -> 2 | K6: =INDEX($Q$12:$Q$14,MATCH(F6,$P$12:$P$14,1)) -> 2 | L6: =INDEX($Q$17:$Q$19,MATCH(I6,$P$17:$P$19,1)) -> 2 | M6: =J6+K6+L6 -> 6 | N6: =INDEX($Q$22:$Q$25,MATCH(M6,$P$22:$P$25,1)) -> Loyal | P6: Days since last order at least | Q6: R score
A7: C003 | B7: Anjali Kulkarni | C7: Corporate | D7: Kolkata | F7: =COUNTIF('Sales Data'!$D$2:$D$1201,A7) -> 2 | G7: =_xlfn.MAXIFS('Sales Data'!$B$2:$B$1201,'Sales Data'!$D$2:$D$1201,A7) -> 45930 | H7: =$Q$4-G7 -> 92 | I7: =SUMIFS('Sales Data'!$P$2:$P$1201,'Sales Data'!$D$2:$D$1201,A7) -> 1420 | J7: =INDEX($Q$7:$Q$9,MATCH(H7,$P$7:$P$9,1)) -> 2 | K7: =INDEX($Q$12:$Q$14,MATCH(F7,$P$12:$P$14,1)) -> 1 | L7: =INDEX($Q$17:$Q$19,MATCH(I7,$P$17:$P$19,1)) -> 1 | M7: =J7+K7+L7 -> 4 | N7: =INDEX($Q$22:$Q$25,MATCH(M7,$P$22:$P$25,1)) -> At Risk | P7: 0 | Q7: 3
A8: C004 | B8: Manoj Nair | C8: Consumer | D8: Pune | F8: =COUNTIF('Sales Data'!$D$2:$D$1201,A8) -> 7 | G8: =_xlfn.MAXIFS('Sales Data'!$B$2:$B$1201,'Sales Data'!$D$2:$D$1201,A8) -> 46008 | H8: =$Q$4-G8 -> 14 | I8: =SUMIFS('Sales Data'!$P$2:$P$1201,'Sales Data'!$D$2:$D$1201,A8) -> 30772 | J8: =INDEX($Q$7:$Q$9,MATCH(H8,$P$7:$P$9,1)) -> 3 | K8: =INDEX($Q$12:$Q$14,MATCH(F8,$P$12:$P$14,1)) -> 3 | L8: =INDEX($Q$17:$Q$19,MATCH(I8,$P$17:$P$19,1)) -> 2 | M8: =J8+K8+L8 -> 8 | N8: =INDEX($Q$22:$Q$25,MATCH(M8,$P$22:$P$25,1)) -> Champion | P8: 46 | Q8: 2
A9: C005 | B9: Kavya Kulkarni | C9: Consumer | D9: Bengaluru | F9: =COUNTIF('Sales Data'!$D$2:$D$1201,A9) -> 2 | G9: =_xlfn.MAXIFS('Sales Data'!$B$2:$B$1201,'Sales Data'!$D$2:$D$1201,A9) -> 45983 | H9: =$Q$4-G9 -> 39 | I9: =SUMIFS('Sales Data'!$P$2:$P$1201,'Sales Data'!$D$2:$D$1201,A9) -> 4754 | J9: =INDEX($Q$7:$Q$9,MATCH(H9,$P$7:$P$9,1)) -> 3 | K9: =INDEX($Q$12:$Q$14,MATCH(F9,$P$12:$P$14,1)) -> 1 | L9: =INDEX($Q$17:$Q$19,MATCH(I9,$P$17:$P$19,1)) -> 1 | M9: =J9+K9+L9 -> 5 | N9: =INDEX($Q$22:$Q$25,MATCH(M9,$P$22:$P$25,1)) -> At Risk | P9: 151 | Q9: 1
A10: C006 | B10: Kunal Bose | C10: Consumer | D10: Kolkata | F10: =COUNTIF('Sales Data'!$D$2:$D$1201,A10) -> 6 | G10: =_xlfn.MAXIFS('Sales Data'!$B$2:$B$1201,'Sales Data'!$D$2:$D$1201,A10) -> 45999 | H10: =$Q$4-G10 -> 23 | I10: =SUMIFS('Sales Data'!$P$2:$P$1201,'Sales Data'!$D$2:$D$1201,A10) -> 20096 | J10: =INDEX($Q$7:$Q$9,MATCH(H10,$P$7:$P$9,1)) -> 3 | K10: =INDEX($Q$12:$Q$14,MATCH(F10,$P$12:$P$14,1)) -> 2 | L10: =INDEX($Q$17:$Q$19,MATCH(I10,$P$17:$P$19,1)) -> 2 | M10: =J10+K10+L10 -> 7 | N10: =INDEX($Q$22:$Q$25,MATCH(M10,$P$22:$P$25,1)) -> Loyal
A11: C007 | B11: Kavya Patel | C11: Consumer | D11: Pune | F11: =COUNTIF('Sales Data'!$D$2:$D$1201,A11) -> 2 | G11: =_xlfn.MAXIFS('Sales Data'!$B$2:$B$1201,'Sales Data'!$D$2:$D$1201,A11) -> 45866 | H11: =$Q$4-G11 -> 156 | I11: =SUMIFS('Sales Data'!$P$2:$P$1201,'Sales Data'!$D$2:$D$1201,A11) -> 3874 | J11: =INDEX($Q$7:$Q$9,MATCH(H11,$P$7:$P$9,1)) -> 1 | K11: =INDEX($Q$12:$Q$14,MATCH(F11,$P$12:$P$14,1)) -> 1 | L11: =INDEX($Q$17:$Q$19,MATCH(I11,$P$17:$P$19,1)) -> 1 | M11: =J11+K11+L11 -> 3 | N11: =INDEX($Q$22:$Q$25,MATCH(M11,$P$22:$P$25,1)) -> Lost | P11: Orders at least | Q11: F score
A12: C008 | B12: Riya Bose | C12: Home Office | D12: Mumbai | F12: =COUNTIF('Sales Data'!$D$2:$D$1201,A12) -> 7 | G12: =_xlfn.MAXIFS('Sales Data'!$B$2:$B$1201,'Sales Data'!$D$2:$D$1201,A12) -> 45976 | H12: =$Q$4-G12 -> 46 | I12: =SUMIFS('Sales Data'!$P$2:$P$1201,'Sales Data'!$D$2:$D$1201,A12) -> 17849 | J12: =INDEX($Q$7:$Q$9,MATCH(H12,$P$7:$P$9,1)) -> 2 | K12: =INDEX($Q$12:$Q$14,MATCH(F12,$P$12:$P$14,1)) -> 3 | L12: =INDEX($Q$17:$Q$19,MATCH(I12,$P$17:$P$19,1)) -> 2 | M12: =J12+K12+L12 -> 7 | N12: =INDEX($Q$22:$Q$25,MATCH(M12,$P$22:$P$25,1)) -> Loyal | P12: 1 | Q12: 1
A13: C009 | B13: Divya Sharma | C13: Consumer | D13: Chennai | F13: =COUNTIF('Sales Data'!$D$2:$D$1201,A13) -> 4 | G13: =_xlfn.MAXIFS('Sales Data'!$B$2:$B$1201,'Sales Data'!$D$2:$D$1201,A13) -> 45965 | H13: =$Q$4-G13 -> 57 | I13: =SUMIFS('Sales Data'!$P$2:$P$1201,'Sales Data'!$D$2:$D$1201,A13) -> 12094 | J13: =INDEX($Q$7:$Q$9,MATCH(H13,$P$7:$P$9,1)) -> 2 | K13: =INDEX($Q$12:$Q$14,MATCH(F13,$P$12:$P$14,1)) -> 2 | L13: =INDEX($Q$17:$Q$19,MATCH(I13,$P$17:$P$19,1)) -> 2 | M13: =J13+K13+L13 -> 6 | N13: =INDEX($Q$22:$Q$25,MATCH(M13,$P$22:$P$25,1)) -> Loyal | P13: 3 | Q13: 2
A14: C010 | B14: Zoya Das | C14: Home Office | D14: Hyderabad | F14: =COUNTIF('Sales Data'!$D$2:$D$1201,A14) -> 3 | G14: =_xlfn.MAXIFS('Sales Data'!$B$2:$B$1201,'Sales Data'!$D$2:$D$1201,A14) -> 45983 | H14: =$Q$4-G14 -> 39 | I14: =SUMIFS('Sales Data'!$P$2:$P$1201,'Sales Data'!$D$2:$D$1201,A14) -> 15734 | J14: =INDEX($Q$7:$Q$9,MATCH(H14,$P$7:$P$9,1)) -> 3 | K14: =INDEX($Q$12:$Q$14,MATCH(F14,$P$12:$P$14,1)) -> 2 | L14: =INDEX($Q$17:$Q$19,MATCH(I14,$P$17:$P$19,1)) -> 2 | M14: =J14+K14+L14 -> 7 | N14: =INDEX($Q$22:$Q$25,MATCH(M14,$P$22:$P$25,1)) -> Loyal | P14: 7 | Q14: 3
A15: C011 | B15: Isha Shah | C15: Consumer | D15: Pune | F15: =COUNTIF('Sales Data'!$D$2:$D$1201,A15) -> 2 | G15: =_xlfn.MAXIFS('Sales Data'!$B$2:$B$1201,'Sales Data'!$D$2:$D$1201,A15) -> 45953 | H15: =$Q$4-G15 -> 69 | I15: =SUMIFS('Sales Data'!$P$2:$P$1201,'Sales Data'!$D$2:$D$1201,A15) -> 4123 | J15: =INDEX($Q$7:$Q$9,MATCH(H15,$P$7:$P$9,1)) -> 2 | K15: =INDEX($Q$12:$Q$14,MATCH(F15,$P$12:$P$14,1)) -> 1 | L15: =INDEX($Q$17:$Q$19,MATCH(I15,$P$17:$P$19,1)) -> 1 | M15: =J15+K15+L15 -> 4 | N15: =INDEX($Q$22:$Q$25,MATCH(M15,$P$22:$P$25,1)) -> At Risk
A16: C012 | B16: Suresh Desai | C16: Home Office | D16: Bengaluru | F16: =COUNTIF('Sales Data'!$D$2:$D$1201,A16) -> 15 | G16: =_xlfn.MAXIFS('Sales Data'!$B$2:$B$1201,'Sales Data'!$D$2:$D$1201,A16) -> 46012 | H16: =$Q$4-G16 -> 10 | I16: =SUMIFS('Sales Data'!$P$2:$P$1201,'Sales Data'!$D$2:$D$1201,A16) -> 80674 | J16: =INDEX($Q$7:$Q$9,MATCH(H16,$P$7:$P$9,1)) -> 3 | K16: =INDEX($Q$12:$Q$14,MATCH(F16,$P$12:$P$14,1)) -> 3 | L16: =INDEX($Q$17:$Q$19,MATCH(I16,$P$17:$P$19,1)) -> 3 | M16: =J16+K16+L16 -> 9 | N16: =INDEX($Q$22:$Q$25,MATCH(M16,$P$22:$P$25,1)) -> Champion | P16: Total Sales at least (₹) | Q16: M score
A17: C013 | B17: Suresh Malhotra | C17: Consumer | D17: Bengaluru | F17: =COUNTIF('Sales Data'!$D$2:$D$1201,A17) -> 6 | G17: =_xlfn.MAXIFS('Sales Data'!$B$2:$B$1201,'Sales Data'!$D$2:$D$1201,A17) -> 45971 | H17: =$Q$4-G17 -> 51 | I17: =SUMIFS('Sales Data'!$P$2:$P$1201,'Sales Data'!$D$2:$D$1201,A17) -> 28689 | J17: =INDEX($Q$7:$Q$9,MATCH(H17,$P$7:$P$9,1)) -> 2 | K17: =INDEX($Q$12:$Q$14,MATCH(F17,$P$12:$P$14,1)) -> 2 | L17: =INDEX($Q$17:$Q$19,MATCH(I17,$P$17:$P$19,1)) -> 2 | M17: =J17+K17+L17 -> 6 | N17: =INDEX($Q$22:$Q$25,MATCH(M17,$P$22:$P$25,1)) -> Loyal | P17: 0 | Q17: 1
A18: C014 | B18: Rahul Jain | C18: Consumer | D18: Bengaluru | F18: =COUNTIF('Sales Data'!$D$2:$D$1201,A18) -> 10 | G18: =_xlfn.MAXIFS('Sales Data'!$B$2:$B$1201,'Sales Data'!$D$2:$D$1201,A18) -> 46021 | H18: =$Q$4-G18 -> 1 | I18: =SUMIFS('Sales Data'!$P$2:$P$1201,'Sales Data'!$D$2:$D$1201,A18) -> 14043 | J18: =INDEX($Q$7:$Q$9,MATCH(H18,$P$7:$P$9,1)) -> 3 | K18: =INDEX($Q$12:$Q$14,MATCH(F18,$P$12:$P$14,1)) -> 3 | L18: =INDEX($Q$17:$Q$19,MATCH(I18,$P$17:$P$19,1)) -> 2 | M18: =J18+K18+L18 -> 8 | N18: =INDEX($Q$22:$Q$25,MATCH(M18,$P$22:$P$25,1)) -> Champion | P18: 12000 | Q18: 2
A19: C015 | B19: Kavya Gupta | C19: Corporate | D19: Kolkata | F19: =COUNTIF('Sales Data'!$D$2:$D$1201,A19) -> 2 | G19: =_xlfn.MAXIFS('Sales Data'!$B$2:$B$1201,'Sales Data'!$D$2:$D$1201,A19) -> 45879 | H19: =$Q$4-G19 -> 143 | I19: =SUMIFS('Sales Data'!$P$2:$P$1201,'Sales Data'!$D$2:$D$1201,A19) -> 5192 | J19: =INDEX($Q$7:$Q$9,MATCH(H19,$P$7:$P$9,1)) -> 2 | K19: =INDEX($Q$12:$Q$14,MATCH(F19,$P$12:$P$14,1)) -> 1 | L19: =INDEX($Q$17:$Q$19,MATCH(I19,$P$17:$P$19,1)) -> 1 | M19: =J19+K19+L19 -> 4 | N19: =INDEX($Q$22:$Q$25,MATCH(M19,$P$22:$P$25,1)) -> At Risk | P19: 45000 | Q19: 3
A20: C016 | B20: Karan Nair | C20: Corporate | D20: Delhi | F20: =COUNTIF('Sales Data'!$D$2:$D$1201,A20) -> 1 | G20: =_xlfn.MAXIFS('Sales Data'!$B$2:$B$1201,'Sales Data'!$D$2:$D$1201,A20) -> 45811 | H20: =$Q$4-G20 -> 211 | I20: =SUMIFS('Sales Data'!$P$2:$P$1201,'Sales Data'!$D$2:$D$1201,A20) -> 479 | J20: =INDEX($Q$7:$Q$9,MATCH(H20,$P$7:$P$9,1)) -> 1 | K20: =INDEX($Q$12:$Q$14,MATCH(F20,$P$12:$P$14,1)) -> 1 | L20: =INDEX($Q$17:$Q$19,MATCH(I20,$P$17:$P$19,1)) -> 1 | M20: =J20+K20+L20 -> 3 | N20: =INDEX($Q$22:$Q$25,MATCH(M20,$P$22:$P$25,1)) -> Lost
A21: C017 | B21: Manoj Saxena | C21: Home Office | D21: Bengaluru | F21: =COUNTIF('Sales Data'!$D$2:$D$1201,A21) -> 8 | G21: =_xlfn.MAXIFS('Sales Data'!$B$2:$B$1201,'Sales Data'!$D$2:$D$1201,A21) -> 45978 | H21: =$Q$4-G21 -> 44 | I21: =SUMIFS('Sales Data'!$P$2:$P$1201,'Sales Data'!$D$2:$D$1201,A21) -> 44172 | J21: =INDEX($Q$7:$Q$9,MATCH(H21,$P$7:$P$9,1)) -> 3 | K21: =INDEX($Q$12:$Q$14,MATCH(F21,$P$12:$P$14,1)) -> 3 | L21: =INDEX($Q$17:$Q$19,MATCH(I21,$P$17:$P$19,1)) -> 2 | M21: =J21+K21+L21 -> 8 | N21: =INDEX($Q$22:$Q$25,MATCH(M21,$P$22:$P$25,1)) -> Champion | P21: Total score at least | Q21: RFM Segment
A22: C018 | B22: Riya Pillai | C22: Home Office | D22: Mumbai | F22: =COUNTIF('Sales Data'!$D$2:$D$1201,A22) -> 8 | G22: =_xlfn.MAXIFS('Sales Data'!$B$2:$B$1201,'Sales Data'!$D$2:$D$1201,A22) -> 45962 | H22: =$Q$4-G22 -> 60 | I22: =SUMIFS('Sales Data'!$P$2:$P$1201,'Sales Data'!$D$2:$D$1201,A22) -> 61007 | J22: =INDEX($Q$7:$Q$9,MATCH(H22,$P$7:$P$9,1)) -> 2 | K22: =INDEX($Q$12:$Q$14,MATCH(F22,$P$12:$P$14,1)) -> 3 | L22: =INDEX($Q$17:$Q$19,MATCH(I22,$P$17:$P$19,1)) -> 3 | M22: =J22+K22+L22 -> 8 | N22: =INDEX($Q$22:$Q$25,MATCH(M22,$P$22:$P$25,1)) -> Champion | P22: 3 | Q22: Lost
A23: C019 | B23: Mohit Rao | C23: Home Office | D23: Bengaluru | F23: =COUNTIF('Sales Data'!$D$2:$D$1201,A23) -> 10 | G23: =_xlfn.MAXIFS('Sales Data'!$B$2:$B$1201,'Sales Data'!$D$2:$D$1201,A23) -> 46021 | H23: =$Q$4-G23 -> 1 | I23: =SUMIFS('Sales Data'!$P$2:$P$1201,'Sales Data'!$D$2:$D$1201,A23) -> 36413 | J23: =INDEX($Q$7:$Q$9,MATCH(H23,$P$7:$P$9,1)) -> 3 | K23: =INDEX($Q$12:$Q$14,MATCH(F23,$P$12:$P$14,1)) -> 3 | L23: =INDEX($Q$17:$Q$19,MATCH(I23,$P$17:$P$19,1)) -> 2 | M23: =J23+K23+L23 -> 8 | N23: =INDEX($Q$22:$Q$25,MATCH(M23,$P$22:$P$25,1)) -> Champion | P23: 4 | Q23: At Risk
A24: C020 | B24: Rahul Pillai | C24: Corporate | D24: Mumbai | F24: =COUNTIF('Sales Data'!$D$2:$D$1201,A24) -> 4 | G24: =_xlfn.MAXIFS('Sales Data'!$B$2:$B$1201,'Sales Data'!$D$2:$D$1201,A24) -> 45960 | H24: =$Q$4-G24 -> 62 | I24: =SUMIFS('Sales Data'!$P$2:$P$1201,'Sales Data'!$D$2:$D$1201,A24) -> 21612 | J24: =INDEX($Q$7:$Q$9,MATCH(H24,$P$7:$P$9,1)) -> 2 | K24: =INDEX($Q$12:$Q$14,MATCH(F24,$P$12:$P$14,1)) -> 2 | L24: =INDEX($Q$17:$Q$19,MATCH(I24,$P$17:$P$19,1)) -> 2 | M24: =J24+K24+L24 -> 6 | N24: =INDEX($Q$22:$Q$25,MATCH(M24,$P$22:$P$25,1)) -> Loyal | P24: 6 | Q24: Loyal
A25: C021 | B25: Rajat Reddy | C25: Consumer | D25: Mumbai | F25: =COUNTIF('Sales Data'!$D$2:$D$1201,A25) -> 4 | G25: =_xlfn.MAXIFS('Sales Data'!$B$2:$B$1201,'Sales Data'!$D$2:$D$1201,A25) -> 45993 | H25: =$Q$4-G25 -> 29 | I25: =SUMIFS('Sales Data'!$P$2:$P$1201,'Sales Data'!$D$2:$D$1201,A25) -> 11555 | J25: =INDEX($Q$7:$Q$9,MATCH(H25,$P$7:$P$9,1)) -> 3 | K25: =INDEX($Q$12:$Q$14,MATCH(F25,$P$12:$P$14,1)) -> 2 | L25: =INDEX($Q$17:$Q$19,MATCH(I25,$P$17:$P$19,1)) -> 1 | M25: =J25+K25+L25 -> 6 | N25: =INDEX($Q$22:$Q$25,MATCH(M25,$P$22:$P$25,1)) -> Loyal | P25: 8 | Q25: Champion
A26: C022 | B26: Gaurav Saxena | C26: Consumer | D26: Mumbai | F26: =COUNTIF('Sales Data'!$D$2:$D$1201,A26) -> 8 | G26: =_xlfn.MAXIFS('Sales Data'!$B$2:$B$1201,'Sales Data'!$D$2:$D$1201,A26) -> 46016 | H26: =$Q$4-G26 -> 6 | I26: =SUMIFS('Sales Data'!$P$2:$P$1201,'Sales Data'!$D$2:$D$1201,A26) -> 49491 | J26: =INDEX($Q$7:$Q$9,MATCH(H26,$P$7:$P$9,1)) -> 3 | K26: =INDEX($Q$12:$Q$14,MATCH(F26,$P$12:$P$14,1)) -> 3 | L26: =INDEX($Q$17:$Q$19,MATCH(I26,$P$17:$P$19,1)) -> 3 | M26: =J26+K26+L26 -> 9 | N26: =INDEX($Q$22:$Q$25,MATCH(M26,$P$22:$P$25,1)) -> Champion
A27: C023 | B27: Sanjay Saxena | C27: Consumer | D27: Bengaluru | F27: =COUNTIF('Sales Data'!$D$2:$D$1201,A27) -> 1 | G27: =_xlfn.MAXIFS('Sales Data'!$B$2:$B$1201,'Sales Data'!$D$2:$D$1201,A27) -> 45963 | H27: =$Q$4-G27 -> 59 | I27: =SUMIFS('Sales Data'!$P$2:$P$1201,'Sales Data'!$D$2:$D$1201,A27) -> 378 | J27: =INDEX($Q$7:$Q$9,MATCH(H27,$P$7:$P$9,1)) -> 2 | K27: =INDEX($Q$12:$Q$14,MATCH(F27,$P$12:$P$14,1)) -> 1 | L27: =INDEX($Q$17:$Q$19,MATCH(I27,$P$17:$P$19,1)) -> 1 | M27: =J27+K27+L27 -> 4 | N27: =INDEX($Q$22:$Q$25,MATCH(M27,$P$22:$P$25,1)) -> At Risk
A28: C024 | B28: Rajat Bhatt | C28: Consumer | D28: Chennai | F28: =COUNTIF('Sales Data'!$D$2:$D$1201,A28) -> 11 | G28: =_xlfn.MAXIFS('Sales Data'!$B$2:$B$1201,'Sales Data'!$D$2:$D$1201,A28) -> 46015 | H28: =$Q$4-G28 -> 7 | I28: =SUMIFS('Sales Data'!$P$2:$P$1201,'Sales Data'!$D$2:$D$1201,A28) -> 39762 | J28: =INDEX($Q$7:$Q$9,MATCH(H28,$P$7:$P$9,1)) -> 3 | K28: =INDEX($Q$12:$Q$14,MATCH(F28,$P$12:$P$14,1)) -> 3 | L28: =INDEX($Q$17:$Q$19,MATCH(I28,$P$17:$P$19,1)) -> 2 | M28: =J28+K28+L28 -> 8 | N28: =INDEX($Q$22:$Q$25,MATCH(M28,$P$22:$P$25,1)) -> Champion
A29: C025 | B29: Zoya Kulkarni | C29: Corporate | D29: Mumbai | F29: =COUNTIF('Sales Data'!$D$2:$D$1201,A29) -> 11 | G29: =_xlfn.MAXIFS('Sales Data'!$B$2:$B$1201,'Sales Data'!$D$2:$D$1201,A29) -> 45982 | H29: =$Q$4-G29 -> 40 | I29: =SUMIFS('Sales Data'!$P$2:$P$1201,'Sales Data'!$D$2:$D$1201,A29) -> 77585 | J29: =INDEX($Q$7:$Q$9,MATCH(H29,$P$7:$P$9,1)) -> 3 | K29: =INDEX($Q$12:$Q$14,MATCH(F29,$P$12:$P$14,1)) -> 3 | L29: =INDEX($Q$17:$Q$19,MATCH(I29,$P$17:$P$19,1)) -> 3 | M29: =J29+K29+L29 -> 9 | N29: =INDEX($Q$22:$Q$25,MATCH(M29,$P$22:$P$25,1)) -> Champion
A30: C026 | B30: Ramesh Bose | C30: Consumer | D30: Mumbai | F30: =COUNTIF('Sales Data'!$D$2:$D$1201,A30) -> 2 | G30: =_xlfn.MAXIFS('Sales Data'!$B$2:$B$1201,'Sales Data'!$D$2:$D$1201,A30) -> 45980 | H30: =$Q$4-G30 -> 42 | I30: =SUMIFS('Sales Data'!$P$2:$P$1201,'Sales Data'!$D$2:$D$1201,A30) -> 29095 | J30: =INDEX($Q$7:$Q$9,MATCH(H30,$P$7:$P$9,1)) -> 3 | K30: =INDEX($Q$12:$Q$14,MATCH(F30,$P$12:$P$14,1)) -> 1 | L30: =INDEX($Q$17:$Q$19,MATCH(I30,$P$17:$P$19,1)) -> 2 | M30: =J30+K30+L30 -> 6 | N30: =INDEX($Q$22:$Q$25,MATCH(M30,$P$22:$P$25,1)) -> Loyal
A31: C027 | B31: Tanvi Kapoor | C31: Consumer | D31: Mumbai | F31: =COUNTIF('Sales Data'!$D$2:$D$1201,A31) -> 4 | G31: =_xlfn.MAXIFS('Sales Data'!$B$2:$B$1201,'Sales Data'!$D$2:$D$1201,A31) -> 45971 | H31: =$Q$4-G31 -> 51 | I31: =SUMIFS('Sales Data'!$P$2:$P$1201,'Sales Data'!$D$2:$D$1201,A31) -> 16734 | J31: =INDEX($Q$7:$Q$9,MATCH(H31,$P$7:$P$9,1)) -> 2 | K31: =INDEX($Q$12:$Q$14,MATCH(F31,$P$12:$P$14,1)) -> 2 | L31: =INDEX($Q$17:$Q$19,MATCH(I31,$P$17:$P$19,1)) -> 2 | M31: =J31+K31+L31 -> 6 | N31: =INDEX($Q$22:$Q$25,MATCH(M31,$P$22:$P$25,1)) -> Loyal
A32: C028 | B32: Deepak Kulkarni | C32: Consumer | D32: Mumbai | F32: =COUNTIF('Sales Data'!$D$2:$D$1201,A32) -> 3 | G32: =_xlfn.MAXIFS('Sales Data'!$B$2:$B$1201,'Sales Data'!$D$2:$D$1201,A32) -> 45964 | H32: =$Q$4-G32 -> 58 | I32: =SUMIFS('Sales Data'!$P$2:$P$1201,'Sales Data'!$D$2:$D$1201,A32) -> 24946 | J32: =INDEX($Q$7:$Q$9,MATCH(H32,$P$7:$P$9,1)) -> 2 | K32: =INDEX($Q$12:$Q$14,MATCH(F32,$P$12:$P$14,1)) -> 2 | L32: =INDEX($Q$17:$Q$19,MATCH(I32,$P$17:$P$19,1)) -> 2 | M32: =J32+K32+L32 -> 6 | N32: =INDEX($Q$22:$Q$25,MATCH(M32,$P$22:$P$25,1)) -> Loyal
A33: C029 | B33: Rajat Patel | C33: Corporate | D33: Bengaluru | F33: =COUNTIF('Sales Data'!$D$2:$D$1201,A33) -> 3 | G33: =_xlfn.MAXIFS('Sales Data'!$B$2:$B$1201,'Sales Data'!$D$2:$D$1201,A33) -> 45966 | H33: =$Q$4-G33 -> 56 | I33: =SUMIFS('Sales Data'!$P$2:$P$1201,'Sales Data'!$D$2:$D$1201,A33) -> 18195 | J33: =INDEX($Q$7:$Q$9,MATCH(H33,$P$7:$P$9,1)) -> 2 | K33: =INDEX($Q$12:$Q$14,MATCH(F33,$P$12:$P$14,1)) -> 2 | L33: =INDEX($Q$17:$Q$19,MATCH(I33,$P$17:$P$19,1)) -> 2 | M33: =J33+K33+L33 -> 6 | N33: =INDEX($Q$22:$Q$25,MATCH(M33,$P$22:$P$25,1)) -> Loyal
A34: C030 | B34: Anjali Joshi | C34: Corporate | D34: Chennai | F34: =COUNTIF('Sales Data'!$D$2:$D$1201,A34) -> 5 | G34: =_xlfn.MAXIFS('Sales Data'!$B$2:$B$1201,'Sales Data'!$D$2:$D$1201,A34) -> 45957 | H34: =$Q$4-G34 -> 65 | I34: =SUMIFS('Sales Data'!$P$2:$P$1201,'Sales Data'!$D$2:$D$1201,A34) -> 24669 | J34: =INDEX($Q$7:$Q$9,MATCH(H34,$P$7:$P$9,1)) -> 2 | K34: =INDEX($Q$12:$Q$14,MATCH(F34,$P$12:$P$14,1)) -> 2 | L34: =INDEX($Q$17:$Q$19,MATCH(I34,$P$17:$P$19,1)) -> 2 | M34: =J34+K34+L34 -> 6 | N34: =INDEX($Q$22:$Q$25,MATCH(M34,$P$22:$P$25,1)) -> Loyal
A35: C031 | B35: Manoj Bose | C35: Consumer | D35: Ahmedabad | F35: =COUNTIF('Sales Data'!$D$2:$D$1201,A35) -> 6 | G35: =_xlfn.MAXIFS('Sales Data'!$B$2:$B$1201,'Sales Data'!$D$2:$D$1201,A35) -> 45886 | H35: =$Q$4-G35 -> 136 | I35: =SUMIFS('Sales Data'!$P$2:$P$1201,'Sales Data'!$D$2:$D$1201,A35) -> 26370 | J35: =INDEX($Q$7:$Q$9,MATCH(H35,$P$7:$P$9,1)) -> 2 | K35: =INDEX($Q$12:$Q$14,MATCH(F35,$P$12:$P$14,1)) -> 2 | L35: =INDEX($Q$17:$Q$19,MATCH(I35,$P$17:$P$19,1)) -> 2 | M35: =J35+K35+L35 -> 6 | N35: =INDEX($Q$22:$Q$25,MATCH(M35,$P$22:$P$25,1)) -> Loyal
A36: C032 | B36: Tanvi Kumar | C36: Consumer | D36: Bengaluru | F36: =COUNTIF('Sales Data'!$D$2:$D$1201,A36) -> 3 | G36: =_xlfn.MAXIFS('Sales Data'!$B$2:$B$1201,'Sales Data'!$D$2:$D$1201,A36) -> 45983 | H36: =$Q$4-G36 -> 39 | I36: =SUMIFS('Sales Data'!$P$2:$P$1201,'Sales Data'!$D$2:$D$1201,A36) -> 2026 | J36: =INDEX($Q$7:$Q$9,MATCH(H36,$P$7:$P$9,1)) -> 3 | K36: =INDEX($Q$12:$Q$14,MATCH(F36,$P$12:$P$14,1)) -> 2 | L36: =INDEX($Q$17:$Q$19,MATCH(I36,$P$17:$P$19,1)) -> 1 | M36: =J36+K36+L36 -> 6 | N36: =INDEX($Q$22:$Q$25,MATCH(M36,$P$22:$P$25,1)) -> Loyal
A37: C033 | B37: Neha Nair | C37: Consumer | D37: Pune | F37: =COUNTIF('Sales Data'!$D$2:$D$1201,A37) -> 2 | G37: =_xlfn.MAXIFS('Sales Data'!$B$2:$B$1201,'Sales Data'!$D$2:$D$1201,A37) -> 45976 | H37: =$Q$4-G37 -> 46 | I37: =SUMIFS('Sales Data'!$P$2:$P$1201,'Sales Data'!$D$2:$D$1201,A37) -> 11998 | J37: =INDEX($Q$7:$Q$9,MATCH(H37,$P$7:$P$9,1)) -> 2 | K37: =INDEX($Q$12:$Q$14,MATCH(F37,$P$12:$P$14,1)) -> 1 | L37: =INDEX($Q$17:$Q$19,MATCH(I37,$P$17:$P$19,1)) -> 1 | M37: =J37+K37+L37 -> 4 | N37: =INDEX($Q$22:$Q$25,MATCH(M37,$P$22:$P$25,1)) -> At Risk
... A224: C220 | B224: Varun Singh | C224: Corporate | D224: Kolkata | F224: =COUNTIF('Sales Data'!$D$2:$D$1201,A224) -> 2 | G224: =_xlfn.MAXIFS('Sales Data'!$B$2:$B$1201,'Sales Data'!$D$2:$D$1201,A224) -> 45891 | H224: =$Q$4-G224 -> 131 | I224: =SUMIFS('Sales Data'!$P$2:$P$1201,'Sales Data'!$D$2:$D$1201,A224) -> 2846 | J224: =INDEX($Q$7:$Q$9,MATCH(H224,$P$7:$P$9,1)) -> 2 | K224: =INDEX($Q$12:$Q$14,MATCH(F224,$P$12:$P$14,1)) -> 1 | L224: =INDEX($Q$17:$Q$19,MATCH(I224,$P$17:$P$19,1)) -> 1 | M224: =J224+K224+L224 -> 4 | N224: =INDEX($Q$22:$Q$25,MATCH(M224,$P$22:$P$25,1)) -> At Risk

Sheet 4 RFM Tasks
A1: 4. Customer RFM analysis
A2: Work on the Customers sheet, then type your answers in the yellow cells.
A4: No. | B4: Task | C4: Your answer | D4: Done? (Y/N)
A5: 1 | B5: Fill Orders, Last Order Date, Days Since Last Order and Total Sales on the Customers sheet. How many customers ordered only once? | C5: =COUNTIF(Customers!$F$5:$F$224,1) -> 29 | D5: Y
A6: 2 | B6: Which customer has the highest Total Sales? Enter the Customer ID. | C6: =INDEX(Customers!$A$5:$A$224,MATCH(MAX(Customers!$I$5:$I$224),Customers!$I$5:$I$224,0)) -> C166 | D6: Y
A7: 3 | B7: What is the highest number of orders placed by one customer? | C7: =MAX(Customers!$F$5:$F$224) -> 20 | D7: Y
A8: 4 | B8: Fill the R, F and M scores, Total Score and RFM Segment using the lookup tables. How many customers are Champions? | C8: =COUNTIF(Customers!$N$5:$N$224,"Champion") -> 67 | D8: Y
A9: 5 | B9: How many customers are Loyal? | C9: =COUNTIF(Customers!$N$5:$N$224,"Loyal") -> 76 | D9: Y
A10: 6 | B10: How many customers are At Risk? | C10: =COUNTIF(Customers!$N$5:$N$224,"At Risk") -> 56 | D10: Y
A11: 7 | B11: How many customers are Lost? | C11: =COUNTIF(Customers!$N$5:$N$224,"Lost") -> 21 | D11: Y
A12: 8 | B12: What are the total Sales (₹) from Champion customers? | C12: =SUMIF(Customers!$N$5:$N$224,"Champion",Customers!$I$5:$I$224) -> 3394545 | D12: Y
A13: 9 | B13: What percentage of all Sales comes from Champion customers? | C13: =C12/SUM(Customers!$I$5:$I$224) -> 0.62552991 | D13: Y

Sheet 5 Dashboard Tasks
A1: 5. Pivot tables, charts and dashboard
A2: Use the Sales Data sheet (or your Sales_Clean query table). Type your answers in the yellow cells.
A4: No. | B4: Task | C4: Your answer | D4: Done? (Y/N)
A5: 1 | B5: Build a PivotTable from Sales Data (put each pivot on its own sheet). Rows = Region, Values = Sum of Sales (₹). Enter the Sales for West. | C5: =Pivots!$B$9 -> 2190302 | D5: Y
A6: 2 | B6: Rows = Category, Columns = Region, Values = Sum of Sales (₹). Enter the value for Electronics in the South column. | C6: =Pivots!$D$16 -> 590693 | D6: Y
A7: 3 | B7: Put Order Date in Rows and group by Months and Quarters. Enter the total Sales (₹) for Quarter 4. | C7: =Pivots!$I$27 -> 1978359 | D7: Y
A8: 4 | B8: Rows = Sub-Category, Values = Sum of Profit (₹), sorted from largest to smallest. Enter the name of the top Sub-Category. | C8: =Pivots!$A$40 -> Audio | D8: Y
A9: 5 | B9: Show Values As > % of Grand Total for Profit by Category. Enter the % for Electronics. | C9: =Pivots!$D$66 -> 0.36928395 | D9: Y
A10: 6 | B10: Add a calculated field Profit Margin = Profit / Sales. Enter the margin for Furniture as a percentage. | C10: =Pivots!$E$67 -> 0.033960594 | D10: Y
A11: 7 | B11: Add a helper column Discount Band on Sales Data (No discount, Up to 20%, Above 20%) and pivot Profit by band. Enter the Profit (₹) for Above 20%. | C11: =SUMIFS('Sales Data'!$R$2:$R$1201,'Sales Data'!$T$2:$T$1201,"Above 20%") -> -47109 | D11: Y
A12: 8 | B12: Insert a pivot chart (clustered column) of Sales by Region and give it a clear title. Mark Y when done. | C12: Y: column chart on the Pivots sheet (regular chart; convert to a PivotChart in Excel) | D12: Y
A13: 9 | B13: Insert slicers for Category and Region and connect them to two pivot tables. Check that both change together. Mark Y when done. | C13: Do in Excel: Insert > Slicer (see README step 5) | D13: N
A14: 10 | B14: Insert a timeline slicer on Order Date and connect it to the same pivot tables. Mark Y when done. | C14: Do in Excel: Insert > Timeline (see README step 5) | D14: N
A15: 11 | B15: Build a one-page dashboard: four KPI cards (Sales, Profit, Margin, Orders), three charts, the slicers and the timeline. Set it to print on one page. Mark Y when done. | C15: Y: Dashboard sheet (4 KPI cards, 3 charts, Region/Category dropdowns, date range, prints on 1 page) | D15: Y
A16: 12 | B16: Click Data > Refresh All and confirm every pivot, chart and KPI card updates. Mark Y when done. | C16: Do in Excel after loading the Power Query | D16: N

Sheet Dashboard
B2: Retail Sales & Profit Dashboard | FY 2025 (₹)
B3: 1,200 cleaned orders, Jan to Dec 2025. Change the yellow cells below and every card and chart updates.
B5: Region | C5: All | D5: Category | E5: All | F5: From | G5: 45658 | H5: To | I5: 46022 | J5: Dropdowns: pick a Region or Category (or All). Type a From / To date.
B7: TOTAL SALES | E7: TOTAL PROFIT | H7: PROFIT MARGIN | K7: ORDERS
B8: =Dash_Calc!B47 -> 5426671 | E8: =Dash_Calc!B48 -> 1212441 | H8: =Dash_Calc!B49 -> 0.22342261 | K8: =Dash_Calc!B50 -> 1200
B10: ="Share of full year: "&TEXT(Dash_Calc!B52,"0.0%") -> Share of full year: 100.0% | E10: ="Share of full year: "&TEXT(Dash_Calc!B53,"0.0%") -> Share of full year: 100.0% | H10: ="Full-year margin: "&TEXT(Dash_Calc!B54,"0.0%") -> Full-year margin: 22.3% | K10: ="Avg order value: ₹"&TEXT(Dash_Calc!B51,"#,##0") -> Avg order value: ₹4,522
H29: Profit by Discount Band (follows the filters)
H30: Band | J30: Orders | K30: Sales (₹) | L30: Profit (₹) | M30: Margin
H31: =Dash_Calc!A41 -> No discount | J31: =Dash_Calc!B41 -> 367 | K31: =Dash_Calc!C41 -> 1494101 | L31: =Dash_Calc!D41 -> 541151 | M31: =Dash_Calc!E41 -> 0.36219171
H32: =Dash_Calc!A42 -> Up to 20% | J32: =Dash_Calc!B42 -> 643 | K32: =Dash_Calc!C42 -> 3062479 | L32: =Dash_Calc!D42 -> 718399 | M32: =Dash_Calc!E42 -> 0.23458087
H33: =Dash_Calc!A43 -> Above 20% | J33: =Dash_Calc!B43 -> 190 | K33: =Dash_Calc!C43 -> 870091 | L33: =Dash_Calc!D43 -> -47109 | M33: =Dash_Calc!E43 -> -0.054142613
H35: Reading it: orders discounted above 20% earn a negative margin, while orders with no discount earn the highest margin. Pick a Category to see if the pattern holds there.
B46: Source: Sales Data sheet (Sales_Clean). Profit = Sales - Cost. All amounts in Indian rupees (₹).

Sheet Pivots
A1: Pivot-style summary tables
A2: Every table is a live SUMIFS/COUNTIFS formula on the Sales Data sheet, so it recalculates when the data changes. Equivalent PivotTables can be inserted in Excel (steps in the repo README).
A4: Pivot 1: Sales (₹) by Region
A5: Region | B5: Sales (₹)
A6: East | B6: =SUMIFS('Sales Data'!$P$2:$P$1201,'Sales Data'!$G$2:$G$1201,A6) -> 333766
A7: North | B7: =SUMIFS('Sales Data'!$P$2:$P$1201,'Sales Data'!$G$2:$G$1201,A7) -> 1155087
A8: South | B8: =SUMIFS('Sales Data'!$P$2:$P$1201,'Sales Data'!$G$2:$G$1201,A8) -> 1747516
A9: West | B9: =SUMIFS('Sales Data'!$P$2:$P$1201,'Sales Data'!$G$2:$G$1201,A9) -> 2190302
A10: Grand Total | B10: =SUM(B6:B9) -> 5426671
A12: Pivot 2: Sales (₹) by Category and Region
A13: Category | B13: East | C13: North | D13: South | E13: West | F13: Grand Total
A14: Apparel | B14: =SUMIFS('Sales Data'!$P$2:$P$1201,'Sales Data'!$I$2:$I$1201,$A14,'Sales Data'!$G$2:$G$1201,B$13) -> 65872 | C14: =SUMIFS('Sales Data'!$P$2:$P$1201,'Sales Data'!$I$2:$I$1201,$A14,'Sales Data'!$G$2:$G$1201,C$13) -> 170807 | D14: =SUMIFS('Sales Data'!$P$2:$P$1201,'Sales Data'!$I$2:$I$1201,$A14,'Sales Data'!$G$2:$G$1201,D$13) -> 223042 | E14: =SUMIFS('Sales Data'!$P$2:$P$1201,'Sales Data'!$I$2:$I$1201,$A14,'Sales Data'!$G$2:$G$1201,E$13) -> 266310 | F14: =SUM(B14:E14) -> 726031
A15: Beauty | B15: =SUMIFS('Sales Data'!$P$2:$P$1201,'Sales Data'!$I$2:$I$1201,$A15,'Sales Data'!$G$2:$G$1201,B$13) -> 20232 | C15: =SUMIFS('Sales Data'!$P$2:$P$1201,'Sales Data'!$I$2:$I$1201,$A15,'Sales Data'!$G$2:$G$1201,C$13) -> 58381 | D15: =SUMIFS('Sales Data'!$P$2:$P$1201,'Sales Data'!$I$2:$I$1201,$A15,'Sales Data'!$G$2:$G$1201,D$13) -> 101907 | E15: =SUMIFS('Sales Data'!$P$2:$P$1201,'Sales Data'!$I$2:$I$1201,$A15,'Sales Data'!$G$2:$G$1201,E$13) -> 133384 | F15: =SUM(B15:E15) -> 313904
A16: Electronics | B16: =SUMIFS('Sales Data'!$P$2:$P$1201,'Sales Data'!$I$2:$I$1201,$A16,'Sales Data'!$G$2:$G$1201,B$13) -> 55821 | C16: =SUMIFS('Sales Data'!$P$2:$P$1201,'Sales Data'!$I$2:$I$1201,$A16,'Sales Data'!$G$2:$G$1201,C$13) -> 255561 | D16: =SUMIFS('Sales Data'!$P$2:$P$1201,'Sales Data'!$I$2:$I$1201,$A16,'Sales Data'!$G$2:$G$1201,D$13) -> 590693 | E16: =SUMIFS('Sales Data'!$P$2:$P$1201,'Sales Data'!$I$2:$I$1201,$A16,'Sales Data'!$G$2:$G$1201,E$13) -> 766140 | F16: =SUM(B16:E16) -> 1668215
A17: Furniture | B17: =SUMIFS('Sales Data'!$P$2:$P$1201,'Sales Data'!$I$2:$I$1201,$A17,'Sales Data'!$G$2:$G$1201,B$13) -> 109431 | C17: =SUMIFS('Sales Data'!$P$2:$P$1201,'Sales Data'!$I$2:$I$1201,$A17,'Sales Data'!$G$2:$G$1201,C$13) -> 489365 | D17: =SUMIFS('Sales Data'!$P$2:$P$1201,'Sales Data'!$I$2:$I$1201,$A17,'Sales Data'!$G$2:$G$1201,D$13) -> 516346 | E17: =SUMIFS('Sales Data'!$P$2:$P$1201,'Sales Data'!$I$2:$I$1201,$A17,'Sales Data'!$G$2:$G$1201,E$13) -> 556943 | F17: =SUM(B17:E17) -> 1672085
A18: Home | B18: =SUMIFS('Sales Data'!$P$2:$P$1201,'Sales Data'!$I$2:$I$1201,$A18,'Sales Data'!$G$2:$G$1201,B$13) -> 63623 | C18: =SUMIFS('Sales Data'!$P$2:$P$1201,'Sales Data'!$I$2:$I$1201,$A18,'Sales Data'!$G$2:$G$1201,C$13) -> 147972 | D18: =SUMIFS('Sales Data'!$P$2:$P$1201,'Sales Data'!$I$2:$I$1201,$A18,'Sales Data'!$G$2:$G$1201,D$13) -> 239056 | E18: =SUMIFS('Sales Data'!$P$2:$P$1201,'Sales Data'!$I$2:$I$1201,$A18,'Sales Data'!$G$2:$G$1201,E$13) -> 369199 | F18: =SUM(B18:E18) -> 819850
A19: Stationery | B19: =SUMIFS('Sales Data'!$P$2:$P$1201,'Sales Data'!$I$2:$I$1201,$A19,'Sales Data'!$G$2:$G$1201,B$13) -> 18787 | C19: =SUMIFS('Sales Data'!$P$2:$P$1201,'Sales Data'!$I$2:$I$1201,$A19,'Sales Data'!$G$2:$G$1201,C$13) -> 33001 | D19: =SUMIFS('Sales Data'!$P$2:$P$1201,'Sales Data'!$I$2:$I$1201,$A19,'Sales Data'!$G$2:$G$1201,D$13) -> 76472 | E19: =SUMIFS('Sales Data'!$P$2:$P$1201,'Sales Data'!$I$2:$I$1201,$A19,'Sales Data'!$G$2:$G$1201,E$13) -> 98326 | F19: =SUM(B19:E19) -> 226586
A20: Grand Total | B20: =SUM(B14:B19) -> 333766 | C20: =SUM(C14:C19) -> 1155087 | D20: =SUM(D14:D19) -> 1747516 | E20: =SUM(E14:E19) -> 2190302 | F20: =SUM(F14:F19) -> 5426671
A22: Pivot 3: Sales, Profit and Orders by Month and Quarter
A23: Month no. | B23: Month | C23: Quarter | D23: Sales (₹) | E23: Profit (₹) | F23: Orders | H23: Quarter | I23: Sales (₹) | J23: Profit (₹) | K23: Share of Sales
A24: 1 | B24: =TEXT(DATE(2025,A24,1),"mmmm") -> January | C24: ="Qtr"&ROUNDUP(A24/3,0) -> Qtr1 | D24: =SUMPRODUCT((MONTH('Sales Data'!$B$2:$B$1201)=A24)*'Sales Data'!$P$2:$P$1201) -> 305327 | E24: =SUMPRODUCT((MONTH('Sales Data'!$B$2:$B$1201)=A24)*'Sales Data'!$R$2:$R$1201) -> 78507 | F24: =SUMPRODUCT(--(MONTH('Sales Data'!$B$2:$B$1201)=A24)) -> 85 | H24: Qtr1 | I24: =SUMIFS($D$24:$D$35,$C$24:$C$35,H24) -> 915428 | J24: =SUMIFS($E$24:$E$35,$C$24:$C$35,H24) -> 180408 | K24: =I24/$I$28 -> 0.16869053
A25: 2 | B25: =TEXT(DATE(2025,A25,1),"mmmm") -> February | C25: ="Qtr"&ROUNDUP(A25/3,0) -> Qtr1 | D25: =SUMPRODUCT((MONTH('Sales Data'!$B$2:$B$1201)=A25)*'Sales Data'!$P$2:$P$1201) -> 310888 | E25: =SUMPRODUCT((MONTH('Sales Data'!$B$2:$B$1201)=A25)*'Sales Data'!$R$2:$R$1201) -> 47508 | F25: =SUMPRODUCT(--(MONTH('Sales Data'!$B$2:$B$1201)=A25)) -> 64 | H25: Qtr2 | I25: =SUMIFS($D$24:$D$35,$C$24:$C$35,H25) -> 1367989 | J25: =SUMIFS($E$24:$E$35,$C$24:$C$35,H25) -> 295359 | K25: =I25/$I$28 -> 0.25208622
A26: 3 | B26: =TEXT(DATE(2025,A26,1),"mmmm") -> March | C26: ="Qtr"&ROUNDUP(A26/3,0) -> Qtr1 | D26: =SUMPRODUCT((MONTH('Sales Data'!$B$2:$B$1201)=A26)*'Sales Data'!$P$2:$P$1201) -> 299213 | E26: =SUMPRODUCT((MONTH('Sales Data'!$B$2:$B$1201)=A26)*'Sales Data'!$R$2:$R$1201) -> 54393 | F26: =SUMPRODUCT(--(MONTH('Sales Data'!$B$2:$B$1201)=A26)) -> 77 | H26: Qtr3 | I26: =SUMIFS($D$24:$D$35,$C$24:$C$35,H26) -> 1164895 | J26: =SUMIFS($E$24:$E$35,$C$24:$C$35,H26) -> 276095 | K26: =I26/$I$28 -> 0.21466107
A27: 4 | B27: =TEXT(DATE(2025,A27,1),"mmmm") -> April | C27: ="Qtr"&ROUNDUP(A27/3,0) -> Qtr2 | D27: =SUMPRODUCT((MONTH('Sales Data'!$B$2:$B$1201)=A27)*'Sales Data'!$P$2:$P$1201) -> 424765 | E27: =SUMPRODUCT((MONTH('Sales Data'!$B$2:$B$1201)=A27)*'Sales Data'!$R$2:$R$1201) -> 90505 | F27: =SUMPRODUCT(--(MONTH('Sales Data'!$B$2:$B$1201)=A27)) -> 79 | H27: Qtr4 | I27: =SUMIFS($D$24:$D$35,$C$24:$C$35,H27) -> 1978359 | J27: =SUMIFS($E$24:$E$35,$C$24:$C$35,H27) -> 460579 | K27: =I27/$I$28 -> 0.36456218
A28: 5 | B28: =TEXT(DATE(2025,A28,1),"mmmm") -> May | C28: ="Qtr"&ROUNDUP(A28/3,0) -> Qtr2 | D28: =SUMPRODUCT((MONTH('Sales Data'!$B$2:$B$1201)=A28)*'Sales Data'!$P$2:$P$1201) -> 444324 | E28: =SUMPRODUCT((MONTH('Sales Data'!$B$2:$B$1201)=A28)*'Sales Data'!$R$2:$R$1201) -> 89104 | F28: =SUMPRODUCT(--(MONTH('Sales Data'!$B$2:$B$1201)=A28)) -> 94 | H28: Grand Total | I28: =SUM(I24:I27) -> 5426671 | J28: =SUM(J24:J27) -> 1212441 | K28: =SUM(K24:K27) -> 1
A29: 6 | B29: =TEXT(DATE(2025,A29,1),"mmmm") -> June | C29: ="Qtr"&ROUNDUP(A29/3,0) -> Qtr2 | D29: =SUMPRODUCT((MONTH('Sales Data'!$B$2:$B$1201)=A29)*'Sales Data'!$P$2:$P$1201) -> 498900 | E29: =SUMPRODUCT((MONTH('Sales Data'!$B$2:$B$1201)=A29)*'Sales Data'!$R$2:$R$1201) -> 115750 | F29: =SUMPRODUCT(--(MONTH('Sales Data'!$B$2:$B$1201)=A29)) -> 83
A30: 7 | B30: =TEXT(DATE(2025,A30,1),"mmmm") -> July | C30: ="Qtr"&ROUNDUP(A30/3,0) -> Qtr3 | D30: =SUMPRODUCT((MONTH('Sales Data'!$B$2:$B$1201)=A30)*'Sales Data'!$P$2:$P$1201) -> 418685 | E30: =SUMPRODUCT((MONTH('Sales Data'!$B$2:$B$1201)=A30)*'Sales Data'!$R$2:$R$1201) -> 92285 | F30: =SUMPRODUCT(--(MONTH('Sales Data'!$B$2:$B$1201)=A30)) -> 94
A31: 8 | B31: =TEXT(DATE(2025,A31,1),"mmmm") -> August | C31: ="Qtr"&ROUNDUP(A31/3,0) -> Qtr3 | D31: =SUMPRODUCT((MONTH('Sales Data'!$B$2:$B$1201)=A31)*'Sales Data'!$P$2:$P$1201) -> 379426 | E31: =SUMPRODUCT((MONTH('Sales Data'!$B$2:$B$1201)=A31)*'Sales Data'!$R$2:$R$1201) -> 90066 | F31: =SUMPRODUCT(--(MONTH('Sales Data'!$B$2:$B$1201)=A31)) -> 98
A32: 9 | B32: =TEXT(DATE(2025,A32,1),"mmmm") -> September | C32: ="Qtr"&ROUNDUP(A32/3,0) -> Qtr3 | D32: =SUMPRODUCT((MONTH('Sales Data'!$B$2:$B$1201)=A32)*'Sales Data'!$P$2:$P$1201) -> 366784 | E32: =SUMPRODUCT((MONTH('Sales Data'!$B$2:$B$1201)=A32)*'Sales Data'!$R$2:$R$1201) -> 93744 | F32: =SUMPRODUCT(--(MONTH('Sales Data'!$B$2:$B$1201)=A32)) -> 97
A33: 10 | B33: =TEXT(DATE(2025,A33,1),"mmmm") -> October | C33: ="Qtr"&ROUNDUP(A33/3,0) -> Qtr4 | D33: =SUMPRODUCT((MONTH('Sales Data'!$B$2:$B$1201)=A33)*'Sales Data'!$P$2:$P$1201) -> 668213 | E33: =SUMPRODUCT((MONTH('Sales Data'!$B$2:$B$1201)=A33)*'Sales Data'!$R$2:$R$1201) -> 169513 | F33: =SUMPRODUCT(--(MONTH('Sales Data'!$B$2:$B$1201)=A33)) -> 149
A34: 11 | B34: =TEXT(DATE(2025,A34,1),"mmmm") -> November | C34: ="Qtr"&ROUNDUP(A34/3,0) -> Qtr4 | D34: =SUMPRODUCT((MONTH('Sales Data'!$B$2:$B$1201)=A34)*'Sales Data'!$P$2:$P$1201) -> 776952 | E34: =SUMPRODUCT((MONTH('Sales Data'!$B$2:$B$1201)=A34)*'Sales Data'!$R$2:$R$1201) -> 176062 | F34: =SUMPRODUCT(--(MONTH('Sales Data'!$B$2:$B$1201)=A34)) -> 168
A35: 12 | B35: =TEXT(DATE(2025,A35,1),"mmmm") -> December | C35: ="Qtr"&ROUNDUP(A35/3,0) -> Qtr4 | D35: =SUMPRODUCT((MONTH('Sales Data'!$B$2:$B$1201)=A35)*'Sales Data'!$P$2:$P$1201) -> 533194 | E35: =SUMPRODUCT((MONTH('Sales Data'!$B$2:$B$1201)=A35)*'Sales Data'!$R$2:$R$1201) -> 115004 | F35: =SUMPRODUCT(--(MONTH('Sales Data'!$B$2:$B$1201)=A35)) -> 112
A36: Grand Total | D36: =SUM(D24:D35) -> 5426671 | E36: =SUM(E24:E35) -> 1212441 | F36: =SUM(F24:F35) -> 1200
A38: Pivot 4: Profit (₹) by Sub-Category, largest to smallest
A39: Sub-Category | B39: Profit (₹)
A40: Audio | B40: =SUMIFS('Sales Data'!$R$2:$R$1201,'Sales Data'!$J$2:$J$1201,A40) -> 305967
A41: Kitchen | B41: =SUMIFS('Sales Data'!$R$2:$R$1201,'Sales Data'!$J$2:$J$1201,A41) -> 142631
A42: Accessories | B42: =SUMIFS('Sales Data'!$R$2:$R$1201,'Sales Data'!$J$2:$J$1201,A42) -> 92704
A43: Footwear | B43: =SUMIFS('Sales Data'!$R$2:$R$1201,'Sales Data'!$J$2:$J$1201,A43) -> 92095
A44: Decor | B44: =SUMIFS('Sales Data'!$R$2:$R$1201,'Sales Data'!$J$2:$J$1201,A44) -> 82731
...

Sheet 6 Insights
A1: 6. Insights and recommendations
A2: Write five findings, each with a number from your analysis and an action a shop owner can take. The grey row shows the format.
A4: No. | B4: Finding (plain language) | C4: Evidence (a number from your work) | D4: Recommendation | E4: Estimated impact (₹)
A5: Ex. | B5: Deep discounts turn orders into losses. | C5: ="Orders with a discount above 20% lost ₹"&TEXT(-SUMIFS('Sales Data'!$R$2:$R$1201,'Sales Data'!$O$2:$O$1201,">0.2"),"#,##0")&" in total." -> Orders with a discount above 20% lost ₹47,109 in total. | D5: Cap discounts at 20% for low-margin categories and review prices of the loss-making products. | E5: =-SUMIFS('Sales Data'!$R$2:$R$1201,'Sales Data'!$O$2:$O$1201,">0.2") -> 47109
